Workbook
Name SAPCrosstab1: AfO!$A$1:$I$228
Name SAPCrosstab10: 'Sales 2019 - 2024'!$N$1:$P$11
Name SAPCrosstab11: 'Sales 2019 - 2024'!$R$1:$T$7
Name SAPCrosstab12: 'Sales 2019 - 2024'!$V$1:$Y$223
Name SAPCrosstab2: 'Sales 2019 - 2024'!$A$1:$E$13213
Name SAPCrosstab3: 'AfO - Leads'!$A$1:$C$49
Name SAPCrosstab4: 'AfO - Leads'!$E$1:$H$51
Name SAPCrosstab5: 'AfO - Leads'!$J$1:$L$49
Name SAPCrosstab6: 'Market Potential'!$A$1:$C$55
Name SAPCrosstab7: 'Market Potential'!$D$1:$E$22
Name SAPCrosstab8: 'Market Potential'!$G$1:$J$229
Name SAPCrosstab9: 'Sales 2019 - 2024'!$H$1:$L$1903

Sheet _com.sap.ip.bi.xl.hiddensheet

Sheet 1 - X5 Template Working File
J2: X5 Targets
A3: Gross Sales ['mio. €] | J3: B2C Applications Beverage
A4: Region | B4: Market Segments L2 | C4: FY 2019 | D4: FY 2020 | E4: FY 2021 | F4: FY 2022 | G4: FY 2023 | H4: BUD 2024 | I4: RunRate 2024 | J4: Beer & Malt Bev. | K4: Cider, Wine, Spirits | L4: Instant & Dry Bev. | M4: Juices & Juice Drnks | N4: Soft Drinks & Waters | O4: Sports,Ener,FuncDrnk | P4: Syrups | Q4: Tea & Coffee Drinks | R4: X5 Growth | S4: FY 2029 (est.) | T4: CAGR '19 - '24 | U4: CAGR '24 - '29
C5: *mio. € | D5: *mio. € | E5: *mio. € | F5: *mio. € | G5: *mio. € | H5: *mio. € | I5: *mio. € | J5: *mio. € | K5: *mio. € | L5: *mio. € | M5: *mio. € | N5: *mio. € | O5: *mio. € | P5: *mio. € | Q5: *mio. € | R5: *mio. € | S5: *mio. € | T5: % | U5: %
A6: Group | B6: Brewery | C6: =SUMIFS(AfO!D:D,AfO!$A:$A,$A$6,AfO!$B:$B,$B6)/1000 -> 165.75023 | D6: =SUMIFS(AfO!E:E,AfO!$A:$A,$A$6,AfO!$B:$B,$B6)/1000 -> 181.95778 | E6: =SUMIFS(AfO!F:F,AfO!$A:$A,$A$6,AfO!$B:$B,$B6)/1000 -> 226.90863 | F6: =SUMIFS(AfO!G:G,AfO!$A:$A,$A$6,AfO!$B:$B,$B6)/1000 -> 276.0359 | G6: =SUMIFS(AfO!H:H,AfO!$A:$A,$A$6,AfO!$B:$B,$B6)/1000 -> 280.99441 | H6: =SUMIFS(AfO!I:I,AfO!$A:$A,$A$6,AfO!$B:$B,$B6)/1000 -> 315.70569 | I6: =SUMIFS(AfO!J:J,AfO!$A:$A,$A$6,AfO!$B:$B,$B6)/1000 -> 305.72125 | J6: =SUM(J14,J22,J30,J38,J46,J54,J62,J70) -> 0 | K6: =SUM(K14,K22,K30,K38,K46,K54,K62,K70) -> 0 | L6: =SUM(L14,L22,L30,L38,L46,L54,L62,L70) -> 0 | M6: =SUM(M14,M22,M30,M38,M46,M54,M62,M70) -> 0 | N6: =SUM(N14,N22,N30,N38,N46,N54,N62,N70) -> 0 | O6: =SUM(O14,O22,O30,O38,O46,O54,O62,O70) -> 0 | P6: =SUM(P14,P22,P30,P38,P46,P54,P62,P70) -> 0 | Q6: =SUM(Q14,Q22,Q30,Q38,Q46,Q54,Q62,Q70) -> 0 | R6: =SUM(J6:Q6) -> 0 | S6: =R6+I6 -> 305.72125 | T6: =(((I6/C6))^(1/5))-1 -> 0.13024943 | U6: =(((S6/I6))^(1/5))-1 -> 0
B7: Cider, Wine & Spirit | C7: =SUMIFS(AfO!D:D,AfO!$A:$A,$A$6,AfO!$B:$B,$B7)/1000 -> 66.58099 | D7: =SUMIFS(AfO!E:E,AfO!$A:$A,$A$6,AfO!$B:$B,$B7)/1000 -> 67.226292 | E7: =SUMIFS(AfO!F:F,AfO!$A:$A,$A$6,AfO!$B:$B,$B7)/1000 -> 80.465685 | F7: =SUMIFS(AfO!G:G,AfO!$A:$A,$A$6,AfO!$B:$B,$B7)/1000 -> 98.636943 | G7: =SUMIFS(AfO!H:H,AfO!$A:$A,$A$6,AfO!$B:$B,$B7)/1000 -> 97.626815 | H7: =SUMIFS(AfO!I:I,AfO!$A:$A,$A$6,AfO!$B:$B,$B7)/1000 -> 108.22972 | I7: =SUMIFS(AfO!J:J,AfO!$A:$A,$A$6,AfO!$B:$B,$B7)/1000 -> 101.28411 | J7: =SUM(J15,J23,J31,J39,J47,J55,J63,J71) -> 0 | K7: =SUM(K15,K23,K31,K39,K47,K55,K63,K71) -> 0 | L7: =SUM(L15,L23,L31,L39,L47,L55,L63,L71) -> 0 | M7: =SUM(M15,M23,M31,M39,M47,M55,M63,M71) -> 0 | N7: =SUM(N15,N23,N31,N39,N47,N55,N63,N71) -> 0 | O7: =SUM(O15,O23,O31,O39,O47,O55,O63,O71) -> 0 | P7: =SUM(P15,P23,P31,P39,P47,P55,P63,P71) -> 0 | Q7: =SUM(Q15,Q23,Q31,Q39,Q47,Q55,Q63,Q71) -> 0 | R7: =SUM(J7:Q7) -> 0 | S7: =R7+I7 -> 101.28411 | T7: =(((I7/C7))^(1/5))-1 -> 0.087522398 | U7: =(((S7/I7))^(1/5))-1 -> 0
B8: Alc. Beverages | C8: =SUM(C6:C7) -> 232.33122 | D8: =SUM(D6:D7) -> 249.18407 | E8: =SUM(E6:E7) -> 307.37431 | F8: =SUM(F6:F7) -> 374.67284 | G8: =SUM(G6:G7) -> 378.62123 | H8: =SUM(H6:H7) -> 423.93541 | I8: =SUM(I6:I7) -> 407.00536 | J8: =SUM(J16,J24,J32,J40,J48,J56,J64,J72) -> 0 | K8: =SUM(K16,K24,K32,K40,K48,K56,K64,K72) -> 0 | L8: =SUM(L16,L24,L32,L40,L48,L56,L64,L72) -> 0 | M8: =SUM(M16,M24,M32,M40,M48,M56,M64,M72) -> 0 | N8: =SUM(N16,N24,N32,N40,N48,N56,N64,N72) -> 0 | O8: =SUM(O16,O24,O32,O40,O48,O56,O64,O72) -> 0 | P8: =SUM(P16,P24,P32,P40,P48,P56,P64,P72) -> 0 | Q8: =SUM(Q16,Q24,Q32,Q40,Q48,Q56,Q64,Q72) -> 0 | R8: =SUM(J8:Q8) -> 0 | S8: =R8+I8 -> 407.00536 | T8: =(((I8/C8))^(1/5))-1 -> 0.11866103 | U8: =(((S8/I8))^(1/5))-1 -> 0
B9: Juice & Juice Drink | C9: =SUMIFS(AfO!D:D,AfO!$A:$A,$A$6,AfO!$B:$B,$B9)/1000 -> 448.51278 | D9: =SUMIFS(AfO!E:E,AfO!$A:$A,$A$6,AfO!$B:$B,$B9)/1000 -> 450.56219 | E9: =SUMIFS(AfO!F:F,AfO!$A:$A,$A$6,AfO!$B:$B,$B9)/1000 -> 524.17919 | F9: =SUMIFS(AfO!G:G,AfO!$A:$A,$A$6,AfO!$B:$B,$B9)/1000 -> 718.52288 | G9: =SUMIFS(AfO!H:H,AfO!$A:$A,$A$6,AfO!$B:$B,$B9)/1000 -> 752.9857 | H9: =SUMIFS(AfO!I:I,AfO!$A:$A,$A$6,AfO!$B:$B,$B9)/1000 -> 839.00331 | I9: =SUMIFS(AfO!J:J,AfO!$A:$A,$A$6,AfO!$B:$B,$B9)/1000 -> 852.00248 | J9: =SUM(J17,J25,J33,J41,J49,J57,J65,J73) -> 0 | K9: =SUM(K17,K25,K33,K41,K49,K57,K65,K73) -> 0 | L9: =SUM(L17,L25,L33,L41,L49,L57,L65,L73) -> 0 | M9: =SUM(M17,M25,M33,M41,M49,M57,M65,M73) -> 0 | N9: =SUM(N17,N25,N33,N41,N49,N57,N65,N73) -> 0 | O9: =SUM(O17,O25,O33,O41,O49,O57,O65,O73) -> 0 | P9: =SUM(P17,P25,P33,P41,P49,P57,P65,P73) -> 0 | Q9: =SUM(Q17,Q25,Q33,Q41,Q49,Q57,Q65,Q73) -> 0 | R9: =SUM(J9:Q9) -> 0 | S9: =R9+I9 -> 852.00248 | T9: =(((I9/C9))^(1/5))-1 -> 0.13692864 | U9: =(((S9/I9))^(1/5))-1 -> 0
B10: Soft Drink | C10: =SUMIFS(AfO!D:D,AfO!$A:$A,$A$6,AfO!$B:$B,$B10)/1000 -> 533.04683 | D10: =SUMIFS(AfO!E:E,AfO!$A:$A,$A$6,AfO!$B:$B,$B10)/1000 -> 537.17507 | E10: =SUMIFS(AfO!F:F,AfO!$A:$A,$A$6,AfO!$B:$B,$B10)/1000 -> 639.48888 | F10: =SUMIFS(AfO!G:G,AfO!$A:$A,$A$6,AfO!$B:$B,$B10)/1000 -> 765.27568 | G10: =SUMIFS(AfO!H:H,AfO!$A:$A,$A$6,AfO!$B:$B,$B10)/1000 -> 818.63761 | H10: =SUMIFS(AfO!I:I,AfO!$A:$A,$A$6,AfO!$B:$B,$B10)/1000 -> 913.72867 | I10: =SUMIFS(AfO!J:J,AfO!$A:$A,$A$6,AfO!$B:$B,$B10)/1000 -> 904.80327 | J10: =SUM(J18,J26,J34,J42,J50,J58,J66,J74) -> 0 | K10: =SUM(K18,K26,K34,K42,K50,K58,K66,K74) -> 0 | L10: =SUM(L18,L26,L34,L42,L50,L58,L66,L74) -> 0 | M10: =SUM(M18,M26,M34,M42,M50,M58,M66,M74) -> 0 | N10: =SUM(N18,N26,N34,N42,N50,N58,N66,N74) -> 0 | O10: =SUM(O18,O26,O34,O42,O50,O58,O66,O74) -> 0 | P10: =SUM(P18,P26,P34,P42,P50,P58,P66,P74) -> 0 | Q10: =SUM(Q18,Q26,Q34,Q42,Q50,Q58,Q66,Q74) -> 0 | R10: =SUM(J10:Q10) -> 0 | S10: =R10+I10 -> 904.80327 | T10: =(((I10/C10))^(1/5))-1 -> 0.1116236 | U10: =(((S10/I10))^(1/5))-1 -> 0
B11: Tea & Coffee | C11: =SUMIFS(AfO!D:D,AfO!$A:$A,$A$6,AfO!$B:$B,$B11)/1000 -> 17.862578 | D11: =SUMIFS(AfO!E:E,AfO!$A:$A,$A$6,AfO!$B:$B,$B11)/1000 -> 13.869647 | E11: =SUMIFS(AfO!F:F,AfO!$A:$A,$A$6,AfO!$B:$B,$B11)/1000 -> 26.047573 | F11: =SUMIFS(AfO!G:G,AfO!$A:$A,$A$6,AfO!$B:$B,$B11)/1000 -> 19.449724 | G11: =SUMIFS(AfO!H:H,AfO!$A:$A,$A$6,AfO!$B:$B,$B11)/1000 -> 43.366981 | H11: =SUMIFS(AfO!I:I,AfO!$A:$A,$A$6,AfO!$B:$B,$B11)/1000 -> 43.8466 | I11: =SUMIFS(AfO!J:J,AfO!$A:$A,$A$6,AfO!$B:$B,$B11)/1000 -> 49.662591 | J11: =SUM(J19,J27,J35,J43,J51,J59,J67,J75) -> 0 | K11: =SUM(K19,K27,K35,K43,K51,K59,K67,K75) -> 0 | L11: =SUM(L19,L27,L35,L43,L51,L59,L67,L75) -> 0 | M11: =SUM(M19,M27,M35,M43,M51,M59,M67,M75) -> 0 | N11: =SUM(N19,N27,N35,N43,N51,N59,N67,N75) -> 0 | O11: =SUM(O19,O27,O35,O43,O51,O59,O67,O75) -> 0 | P11: =SUM(P19,P27,P35,P43,P51,P59,P67,P75) -> 0 | Q11: =SUM(Q19,Q27,Q35,Q43,Q51,Q59,Q67,Q75) -> 0 | R11: =SUM(J11:Q11) -> 0 | S11: =R11+I11 -> 49.662591 | T11: =(((I11/C11))^(1/5))-1 -> 0.22692226 | U11: =(((S11/I11))^(1/5))-1 -> 0
B12: Non-Alc. Beverages | C12: =SUM(C9:C11) -> 999.42219 | D12: =SUM(D9:D11) -> 1001.6069 | E12: =SUM(E9:E11) -> 1189.7157 | F12: =SUM(F9:F11) -> 1503.2483 | G12: =SUM(G9:G11) -> 1614.9903 | H12: =SUM(H9:H11) -> 1796.5786 | I12: =SUM(I9:I11) -> 1806.4683 | J12: =SUM(J20,J28,J36,J44,J52,J60,J68,J76) -> 0 | K12: =SUM(K20,K28,K36,K44,K52,K60,K68,K76) -> 0 | L12: =SUM(L20,L28,L36,L44,L52,L60,L68,L76) -> 0 | M12: =SUM(M20,M28,M36,M44,M52,M60,M68,M76) -> 0 | N12: =SUM(N20,N28,N36,N44,N52,N60,N68,N76) -> 0 | O12: =SUM(O20,O28,O36,O44,O52,O60,O68,O76) -> 0 | P12: =SUM(P20,P28,P36,P44,P52,P60,P68,P76) -> 0 | Q12: =SUM(Q20,Q28,Q36,Q44,Q52,Q60,Q68,Q76) -> 0 | R12: =SUM(J12:Q12) -> 0 | S12: =R12+I12 -> 1806.4683 | T12: =(((I12/C12))^(1/5))-1 -> 0.12568343 | U12: =(((S12/I12))^(1/5))-1 -> 0
A13: Overall | B13: Result | C13: =SUMIFS(AfO!D:D,AfO!$A:$A,$A$6,AfO!$B:$B,$B13)/1000 -> 1740.6113 | D13: =SUMIFS(AfO!E:E,AfO!$A:$A,$A$6,AfO!$B:$B,$B13)/1000 -> 1789.7402 | E13: =SUMIFS(AfO!F:F,AfO!$A:$A,$A$6,AfO!$B:$B,$B13)/1000 -> 2161.4626 | F13: =SUMIFS(AfO!G:G,AfO!$A:$A,$A$6,AfO!$B:$B,$B13)/1000 -> 2722.0949 | G13: =SUMIFS(AfO!H:H,AfO!$A:$A,$A$6,AfO!$B:$B,$B13)/1000 -> 2872.4323 | H13: =SUMIFS(AfO!I:I,AfO!$A:$A,$A$6,AfO!$B:$B,$B13)/1000 -> 3372.8648 | I13: =SUMIFS(AfO!J:J,AfO!$A:$A,$A$6,AfO!$B:$B,$B13)/1000 -> 3266.363 | J13: =SUM(J21,J29,J37,J45,J53,J61,J69,J77) -> 0 | K13: =SUM(K21,K29,K37,K45,K53,K61,K69,K77) -> 0 | L13: =SUM(L21,L29,L37,L45,L53,L61,L69,L77) -> 0 | M13: =SUM(M21,M29,M37,M45,M53,M61,M69,M77) -> 0 | N13: =SUM(N21,N29,N37,N45,N53,N61,N69,N77) -> 0 | O13: =SUM(O21,O29,O37,O45,O53,O61,O69,O77) -> 0 | P13: =SUM(P21,P29,P37,P45,P53,P61,P69,P77) -> 0 | Q13: =SUM(Q21,Q29,Q37,Q45,Q53,Q61,Q69,Q77) -> 0 | R13: =SUM(J13:Q13) -> 0 | S13: =R13+I13 -> 3266.363 | T13: =(((I13/C13))^(1/5))-1 -> 0.1341553 | U13: =(((S13/I13))^(1/5))-1 -> 0
A14: EUR | B14: Brewery | C14: =SUMIFS(AfO!D:D,AfO!$A:$A,$A$14,AfO!$B:$B,$B14)/1000 -> 97.999654 | D14: =SUMIFS(AfO!E:E,AfO!$A:$A,$A$14,AfO!$B:$B,$B14)/1000 -> 100.43935 | E14: =SUMIFS(AfO!F:F,AfO!$A:$A,$A$14,AfO!$B:$B,$B14)/1000 -> 110.24313 | F14: =SUMIFS(AfO!G:G,AfO!$A:$A,$A$14,AfO!$B:$B,$B14)/1000 -> 122.20181 | G14: =SUMIFS(AfO!H:H,AfO!$A:$A,$A$14,AfO!$B:$B,$B14)/1000 -> 121.60873 | H14: =SUMIFS(AfO!I:I,AfO!$A:$A,$A$14,AfO!$B:$B,$B14)/1000 -> 140.2787 | I14: =SUMIFS(AfO!J:J,AfO!$A:$A,$A$14,AfO!$B:$B,$B14)/1000 -> 150.31435 | R14: =SUM(J14:Q14) -> 0 | S14: =R14+I14 -> 150.31435 | T14: =(((I14/C14))^(1/5))-1 -> 0.089319259 | U14: =(((S14/I14))^(1/5))-1 -> 0
B15: Cider, Wine & Spirit | C15: =SUMIFS(AfO!D:D,AfO!$A:$A,$A$14,AfO!$B:$B,$B15)/1000 -> 52.067942 | D15: =SUMIFS(AfO!E:E,AfO!$A:$A,$A$14,AfO!$B:$B,$B15)/1000 -> 54.05732 | E15: =SUMIFS(AfO!F:F,AfO!$A:$A,$A$14,AfO!$B:$B,$B15)/1000 -> 56.933623 | F15: =SUMIFS(AfO!G:G,AfO!$A:$A,$A$14,AfO!$B:$B,$B15)/1000 -> 68.938936 | G15: =SUMIFS(AfO!H:H,AfO!$A:$A,$A$14,AfO!$B:$B,$B15)/1000 -> 66.889477 | H15: =SUMIFS(AfO!I:I,AfO!$A:$A,$A$14,AfO!$B:$B,$B15)/1000 -> 73.8833 | I15: =SUMIFS(AfO!J:J,AfO!$A:$A,$A$14,AfO!$B:$B,$B15)/1000 -> 67.038592 | R15: =SUM(J15:Q15) -> 0 | S15: =R15+I15 -> 67.038592 | T15: =(((I15/C15))^(1/5))-1 -> 0.051842934 | U15: =(((S15/I15))^(1/5))-1 -> 0
B16: Alc. Beverages | C16: =SUM(C14:C15) -> 150.0676 | D16: =SUM(D14:D15) -> 154.49667 | E16: =SUM(E14:E15) -> 167.17675 | F16: =SUM(F14:F15) -> 191.14074 | G16: =SUM(G14:G15) -> 188.49821 | H16: =SUM(H14:H15) -> 214.162 | I16: =SUM(I14:I15) -> 217.35295 | R16: =SUM(J16:Q16) -> 0 | S16: =R16+I16 -> 217.35295 | T16: =(((I16/C16))^(1/5))-1 -> 0.076900852 | U16: =(((S16/I16))^(1/5))-1 -> 0
B17: Juice & Juice Drink | C17: =SUMIFS(AfO!D:D,AfO!$A:$A,$A$14,AfO!$B:$B,$B17)/1000 -> 261.99452 | D17: =SUMIFS(AfO!E:E,AfO!$A:$A,$A$14,AfO!$B:$B,$B17)/1000 -> 278.46378 | E17: =SUMIFS(AfO!F:F,AfO!$A:$A,$A$14,AfO!$B:$B,$B17)/1000 -> 299.57684 | F17: =SUMIFS(AfO!G:G,AfO!$A:$A,$A$14,AfO!$B:$B,$B17)/1000 -> 365.92302 | G17: =SUMIFS(AfO!H:H,AfO!$A:$A,$A$14,AfO!$B:$B,$B17)/1000 -> 376.34058 | H17: =SUMIFS(AfO!I:I,AfO!$A:$A,$A$14,AfO!$B:$B,$B17)/1000 -> 405.59679 | I17: =SUMIFS(AfO!J:J,AfO!$A:$A,$A$14,AfO!$B:$B,$B17)/1000 -> 429.72051 | R17: =SUM(J17:Q17) -> 0 | S17: =R17+I17 -> 429.72051 | T17: =(((I17/C17))^(1/5))-1 -> 0.10402466 | U17: =(((S17/I17))^(1/5))-1 -> 0
B18: Soft Drink | C18: =SUMIFS(AfO!D:D,AfO!$A:$A,$A$14,AfO!$B:$B,$B18)/1000 -> 343.01031 | D18: =SUMIFS(AfO!E:E,AfO!$A:$A,$A$14,AfO!$B:$B,$B18)/1000 -> 333.31249 | E18: =SUMIFS(AfO!F:F,AfO!$A:$A,$A$14,AfO!$B:$B,$B18)/1000 -> 349.99055 | F18: =SUMIFS(AfO!G:G,AfO!$A:$A,$A$14,AfO!$B:$B,$B18)/1000 -> 390.58592 | G18: =SUMIFS(AfO!H:H,AfO!$A:$A,$A$14,AfO!$B:$B,$B18)/1000 -> 423.03394 | H18: =SUMIFS(AfO!I:I,AfO!$A:$A,$A$14,AfO!$B:$B,$B18)/1000 -> 465.71905 | I18: =SUMIFS(AfO!J:J,AfO!$A:$A,$A$14,AfO!$B:$B,$B18)/1000 -> 469.60336 | R18: =SUM(J18:Q18) -> 0 | S18: =R18+I18 -> 469.60336 | T18: =(((I18/C18))^(1/5))-1 -> 0.064841094 | U18: =(((S18/I18))^(1/5))-1 -> 0
B19: Tea & Coffee | C19: =SUMIFS(AfO!D:D,AfO!$A:$A,$A$14,AfO!$B:$B,$B19)/1000 -> 5.610625 | D19: =SUMIFS(AfO!E:E,AfO!$A:$A,$A$14,AfO!$B:$B,$B19)/1000 -> 6.6683898 | E19: =SUMIFS(AfO!F:F,AfO!$A:$A,$A$14,AfO!$B:$B,$B19)/1000 -> 8.3057916 | F19: =SUMIFS(AfO!G:G,AfO!$A:$A,$A$14,AfO!$B:$B,$B19)/1000 -> 12.354032 | G19: =SUMIFS(AfO!H:H,AfO!$A:$A,$A$14,AfO!$B:$B,$B19)/1000 -> 34.76055 | H19: =SUMIFS(AfO!I:I,AfO!$A:$A,$A$14,AfO!$B:$B,$B19)/1000 -> 21.997327 | I19: =SUMIFS(AfO!J:J,AfO!$A:$A,$A$14,AfO!$B:$B,$B19)/1000 -> 28.611594 | R19: =SUM(J19:Q19) -> 0 | S19: =R19+I19 -> 28.611594 | T19: =(((I19/C19))^(1/5))-1 -> 0.38517984 | U19: =(((S19/I19))^(1/5))-1 -> 0
B20: Non-Alc. Beverages | C20: =SUM(C17:C19) -> 610.61546 | D20: =SUM(D17:D19) -> 618.44466 | E20: =SUM(E17:E19) -> 657.87318 | F20: =SUM(F17:F19) -> 768.86297 | G20: =SUM(G17:G19) -> 834.13507 | H20: =SUM(H17:H19) -> 893.31317 | I20: =SUM(I17:I19) -> 927.93546 | R20: =SUM(J20:Q20) -> 0 | S20: =R20+I20 -> 927.93546 | T20: =(((I20/C20))^(1/5))-1 -> 0.08730152 | U20: =(((S20/I20))^(1/5))-1 -> 0
A21: EUR | B21: Result | C21: =SUMIFS(AfO!D:D,AfO!$A:$A,$A$14,AfO!$B:$B,$B21)/1000 -> 1002.3255 | D21: =SUMIFS(AfO!E:E,AfO!$A:$A,$A$14,AfO!$B:$B,$B21)/1000 -> 1027.1281 | E21: =SUMIFS(AfO!F:F,AfO!$A:$A,$A$14,AfO!$B:$B,$B21)/1000 -> 1132.78 | F21: =SUMIFS(AfO!G:G,AfO!$A:$A,$A$14,AfO!$B:$B,$B21)/1000 -> 1334.6647 | G21: =SUMIFS(AfO!H:H,AfO!$A:$A,$A$14,AfO!$B:$B,$B21)/1000 -> 1427.9009 | H21: =SUMIFS(AfO!I:I,AfO!$A:$A,$A$14,AfO!$B:$B,$B21)/1000 -> 1623.8557 | I21: =SUMIFS(AfO!J:J,AfO!$A:$A,$A$14,AfO!$B:$B,$B21)/1000 -> 1658.2837 | R21: =SUM(J21:Q21) -> 0 | S21: =R21+I21 -> 1658.2837 | T21: =(((I21/C21))^(1/5))-1 -> 0.10593604 | U21: =(((S21/I21))^(1/5))-1 -> 0
A22: CIS | B22: Brewery | C22: =SUMIFS(AfO!D:D,AfO!$A:$A,$A$22,AfO!$B:$B,$B22)/1000 -> 27.557979 | D22: =SUMIFS(AfO!E:E,AfO!$A:$A,$A$22,AfO!$B:$B,$B22)/1000 -> 34.026537 | E22: =SUMIFS(AfO!F:F,AfO!$A:$A,$A$22,AfO!$B:$B,$B22)/1000 -> 40.808168 | F22: =SUMIFS(AfO!G:G,AfO!$A:$A,$A$22,AfO!$B:$B,$B22)/1000 -> 59.492633 | G22: =SUMIFS(AfO!H:H,AfO!$A:$A,$A$22,AfO!$B:$B,$B22)/1000 -> 78.140682 | H22: =SUMIFS(AfO!I:I,AfO!$A:$A,$A$22,AfO!$B:$B,$B22)/1000 -> 83.286073 | I22: =SUMIFS(AfO!J:J,AfO!$A:$A,$A$22,AfO!$B:$B,$B22)/1000 -> 81.515774 | R22: =SUM(J22:Q22) -> 0 | S22: =R22+I22 -> 81.515774 | T22: =(((I22/C22))^(1/5))-1 -> 0.24222098 | U22: =(((S22/I22))^(1/5))-1 -> 0
B23: Cider, Wine & Spirit | C23: =SUMIFS(AfO!D:D,AfO!$A:$A,$A$22,AfO!$B:$B,$B23)/1000 -> 4.9480509 | D23: =SUMIFS(AfO!E:E,AfO!$A:$A,$A$22,AfO!$B:$B,$B23)/1000 -> 4.9606367 | E23: =SUMIFS(AfO!F:F,AfO!$A:$A,$A$22,AfO!$B:$B,$B23)/1000 -> 6.6925095 | F23: =SUMIFS(AfO!G:G,AfO!$A:$A,$A$22,AfO!$B:$B,$B23)/1000 -> 8.8634774 | G23: =SUMIFS(AfO!H:H,AfO!$A:$A,$A$22,AfO!$B:$B,$B23)/1000 -> 10.46572 | H23: =SUMIFS(AfO!I:I,AfO!$A:$A,$A$22,AfO!$B:$B,$B23)/1000 -> 10.913152 | I23: =SUMIFS(AfO!J:J,AfO!$A:$A,$A$22,AfO!$B:$B,$B23)/1000 -> 10.162663 | R23: =SUM(J23:Q23) -> 0 | S23: =R23+I23 -> 10.162663 | T23: =(((I23/C23))^(1/5))-1 -> 0.15482099 | U23: =(((S23/I23))^(1/5))-1 -> 0
B24: Alc. Beverages | C24: =SUM(C22:C23) -> 32.50603 | D24: =SUM(D22:D23) -> 38.987173 | E24: =SUM(E22:E23) -> 47.500677 | F24: =SUM(F22:F23) -> 68.356111 | G24: =SUM(G22:G23) -> 88.606403 | H24: =SUM(H22:H23) -> 94.199225 | I24: =SUM(I22:I23) -> 91.678436 | R24: =SUM(J24:Q24) -> 0 | S24: =R24+I24 -> 91.678436 | T24: =(((I24/C24))^(1/5))-1 -> 0.2304406 | U24: =(((S24/I24))^(1/5))-1 -> 0
B25: Juice & Juice Drink | C25: =SUMIFS(AfO!D:D,AfO!$A:$A,$A$22,AfO!$B:$B,$B25)/1000 -> 24.904139 | D25: =SUMIFS(AfO!E:E,AfO!$A:$A,$A$22,AfO!$B:$B,$B25)/1000 -> 25.904293 | E25: =SUMIFS(AfO!F:F,AfO!$A:$A,$A$22,AfO!$B:$B,$B25)/1000 -> 40.460769 | F25: =SUMIFS(AfO!G:G,AfO!$A:$A,$A$22,AfO!$B:$B,$B25)/1000 -> 47.809997 | G25: =SUMIFS(AfO!H:H,AfO!$A:$A,$A$22,AfO!$B:$B,$B25)/1000 -> 47.678844 | H25: =SUMIFS(AfO!I:I,AfO!$A:$A,$A$22,AfO!$B:$B,$B25)/1000 -> 48.234836 | I25: =SUMIFS(AfO!J:J,AfO!$A:$A,$A$22,AfO!$B:$B,$B25)/1000 -> 49.061505 | R25: =SUM(J25:Q25) -> 0 | S25: =R25+I25 -> 49.061505 | T25: =(((I25/C25))^(1/5))-1 -> 0.14523303 | U25: =(((S25/I25))^(1/5))-1 -> 0
B26: Soft Drink | C26: =SUMIFS(AfO!D:D,AfO!$A:$A,$A$22,AfO!$B:$B,$B26)/1000 -> 50.91124 | D26: =SUMIFS(AfO!E:E,AfO!$A:$A,$A$22,AfO!$B:$B,$B26)/1000 -> 51.96288 | E26: =SUMIFS(AfO!F:F,AfO!$A:$A,$A$22,AfO!$B:$B,$B26)/1000 -> 60.896476 | F26: =SUMIFS(AfO!G:G,AfO!$A:$A,$A$22,AfO!$B:$B,$B26)/1000 -> 88.767684 | G26: =SUMIFS(AfO!H:H,AfO!$A:$A,$A$22,AfO!$B:$B,$B26)/1000 -> 101.15826 | H26: =SUMIFS(AfO!I:I,AfO!$A:$A,$A$22,AfO!$B:$B,$B26)/1000 -> 107.84782 | I26: =SUMIFS(AfO!J:J,AfO!$A:$A,$A$22,AfO!$B:$B,$B26)/1000 -> 111.67105 | R26: =SUM(J26:Q26) -> 0 | S26: =R26+I26 -> 111.67105 | T26: =(((I26/C26))^(1/5))-1 -> 0.17010647 | U26: =(((S26/I26))^(1/5))-1 -> 0
B27: Tea & Coffee | C27: =SUMIFS(AfO!D:D,AfO!$A:$A,$A$22,AfO!$B:$B,$B27)/1000 -> 0.03437503 | D27: =SUMIFS(AfO!E:E,AfO!$A:$A,$A$22,AfO!$B:$B,$B27)/1000 -> 0.00562934 | E27: =SUMIFS(AfO!F:F,AfO!$A:$A,$A$22,AfO!$B:$B,$B27)/1000 -> 0.00759373 | F27: =SUMIFS(AfO!G:G,AfO!$A:$A,$A$22,AfO!$B:$B,$B27)/1000 -> 0.00245045 | G27: =SUMIFS(AfO!H:H,AfO!$A:$A,$A$22,AfO!$B:$B,$B27)/1000 -> 0.00267864 | H27: =SUMIFS(AfO!I:I,AfO!$A:$A,$A$22,AfO!$B:$B,$B27)/1000 -> 0.00279078 | I27: =SUMIFS(AfO!J:J,AfO!$A:$A,$A$22,AfO!$B:$B,$B27)/1000 -> 0.00251298 | R27: =SUM(J27:Q27) -> 0 | S27: =R27+I27 -> 0.00251298 | T27: =(((I27/C27))^(1/5))-1 -> -0.40736242 | U27: =(((S27/I27))^(1/5))-1 -> 0
B28: Non-Alc. Beverages | C28: =SUM(C25:C27) -> 75.849754 | D28: =SUM(D25:D27) -> 77.872802 | E28: =SUM(E25:E27) -> 101.36484 | F28: =SUM(F25:F27) -> 136.58013 | G28: =SUM(G25:G27) -> 148.83979 | H28: =SUM(H25:H27) -> 156.08544 | I28: =SUM(I25:I27) -> 160.73506 | R28: =SUM(J28:Q28) -> 0 | S28: =R28+I28 -> 160.73506 | T28: =(((I28/C28))^(1/5))-1 -> 0.16206732 | U28: =(((S28/I28))^(1/5))-1 -> 0
A29: CIS | B29: Result | C29: =SUMIFS(AfO!D:D,AfO!$A:$A,$A$22,AfO!$B:$B,$B29)/1000 -> 134.48379 | D29: =SUMIFS(AfO!E:E,AfO!$A:$A,$A$22,AfO!$B:$B,$B29)/1000 -> 153.57053 | E29: =SUMIFS(AfO!F:F,AfO!$A:$A,$A$22,AfO!$B:$B,$B29)/1000 -> 190.21406 | F29: =SUMIFS(AfO!G:G,AfO!$A:$A,$A$22,AfO!$B:$B,$B29)/1000 -> 254.85824 | G29: =SUMIFS(AfO!H:H,AfO!$A:$A,$A$22,AfO!$B:$B,$B29)/1000 -> 286.46813 | H29: =SUMIFS(AfO!I:I,AfO!$A:$A,$A$22,AfO!$B:$B,$B29)/1000 -> 303.1095 | I29: =SUMIFS(AfO!J:J,AfO!$A:$A,$A$22,AfO!$B:$B,$B29)/1000 -> 292.76585 | R29: =SUM(J29:Q29) -> 0 | S29: =R29+I29 -> 292.76585 | T29: =(((I29/C29))^(1/5))-1 -> 0.16834229 | U29: =(((S29/I29))^(1/5))-1 -> 0
A30: MEA | B30: Brewery | C30: =SUMIFS(AfO!D:D,AfO!$A:$A,$A$30,AfO!$B:$B,$B30)/1000 -> 10.025434 | D30: =SUMIFS(AfO!E:E,AfO!$A:$A,$A$30,AfO!$B:$B,$B30)/1000 -> 2.4862199 | E30: =SUMIFS(AfO!F:F,AfO!$A:$A,$A$30,AfO!$B:$B,$B30)/1000 -> 9.496856 | F30: =SUMIFS(AfO!G:G,AfO!$A:$A,$A$30,AfO!$B:$B,$B30)/1000 -> 16.853422 | G30: =SUMIFS(AfO!H:H,AfO!$A:$A,$A$30,AfO!$B:$B,$B30)/1000 -> 19.249253 | H30: =SUMIFS(AfO!I:I,AfO!$A:$A,$A$30,AfO!$B:$B,$B30)/1000 -> 20.831869 | I30: =SUMIFS(AfO!J:J,AfO!$A:$A,$A$30,AfO!$B:$B,$B30)/1000 -> 13.086355 | R30: =SUM(J30:Q30) -> 0 | S30: =R30+I30 -> 13.086355 | T30: =(((I30/C30))^(1/5))-1 -> 0.05473439 | U30: =(((S30/I30))^(1/5))-1 -> 0
B31: Cider, Wine & Spirit | C31: =SUMIFS(AfO!D:D,AfO!$A:$A,$A$30,AfO!$B:$B,$B31)/1000 -> 3.9762726 | D31: =SUMIFS(AfO!E:E,AfO!$A:$A,$A$30,AfO!$B:$B,$B31)/1000 -> 4.1155043 | E31: =SUMIFS(AfO!F:F,AfO!$A:$A,$A$30,AfO!$B:$B,$B31)/1000 -> 7.802599 | F31: =SUMIFS(AfO!G:G,AfO!$A:$A,$A$30,AfO!$B:$B,$B31)/1000 -> 9.965696 | G31: =SUMIFS(AfO!H:H,AfO!$A:$A,$A$30,AfO!$B:$B,$B31)/1000 -> 8.1696931 | H31: =SUMIFS(AfO!I:I,AfO!$A:$A,$A$30,AfO!$B:$B,$B31)/1000 -> 9.6389157 | I31: =SUMIFS(AfO!J:J,AfO!$A:$A,$A$30,AfO!$B:$B,$B31)/1000 -> 13.493692 | R31: =SUM(J31:Q31) -> 0 | S31: =R31+I31 -> 13.493692 | T31: =(((I31/C31))^(1/5))-1 -> 0.27682368 | U31: =(((S31/I31))^(1/5))-1 -> 0
B32: Alc. Beverages | C32: =SUM(C30:C31) -> 14.001706 | D32: =SUM(D30:D31) -> 6.6017241 | E32: =SUM(E30:E31) -> 17.299455 | F32: =SUM(F30:F31) -> 26.819118 | G32: =SUM(G30:G31) -> 27.418946 | H32: =SUM(H30:H31) -> 30.470784 | I32: =SUM(I30:I31) -> 26.580047 | R32: =SUM(J32:Q32) -> 0 | S32: =R32+I32 -> 26.580047 | T32: =(((I32/C32))^(1/5))-1 -> 0.13677616 | U32: =(((S32/I32))^(1/5))-1 -> 0
B33: Juice & Juice Drink | C33: =SUMIFS(AfO!D:D,AfO!$A:$A,$A$30,AfO!$B:$B,$B33)/1000 -> 33.644841 | D33: =SUMIFS(AfO!E:E,AfO!$A:$A,$A$30,AfO!$B:$B,$B33)/1000 -> 40.316276 | E33: =SUMIFS(AfO!F:F,AfO!$A:$A,$A$30,AfO!$B:$B,$B33)/1000 -> 47.183211 | F33: =SUMIFS(AfO!G:G,AfO!$A:$A,$A$30,AfO!$B:$B,$B33)/1000 -> 60.248435 | G33: =SUMIFS(AfO!H:H,AfO!$A:$A,$A$30,AfO!$B:$B,$B33)/1000 -> 76.822222 | H33: =SUMIFS(AfO!I:I,AfO!$A:$A,$A$30,AfO!$B:$B,$B33)/1000 -> 86.969503 | I33: =SUMIFS(AfO!J:J,AfO!$A:$A,$A$30,AfO!$B:$B,$B33)/1000 -> 87.657356 | R33: =SUM(J33:Q33) -> 0 | S33: =R33+I33 -> 87.657356 | T33: =(((I33/C33))^(1/5))-1 -> 0.21108319 | U33: =(((S33/I33))^(1/5))-1 -> 0
B34: Soft Drink | C34: =SUMIFS(AfO!D:D,AfO!$A:$A,$A$30,AfO!$B:$B,$B34)/1000 -> 48.869823 | D34: =SUMIFS(AfO!E:E,AfO!$A:$A,$A$30,AfO!$B:$B,$B34)/1000 -> 48.83479 | E34: =SUMIFS(AfO!F:F,AfO!$A:$A,$A$30,AfO!$B:$B,$B34)/1000 -> 79.221321 | F34: =SUMIFS(AfO!G:G,AfO!$A:$A,$A$30,AfO!$B:$B,$B34)/1000 -> 101.80888 | G34: =SUMIFS(AfO!H:H,AfO!$A:$A,$A$30,AfO!$B:$B,$B34)/1000 -> 99.93534 | H34: =SUMIFS(AfO!I:I,AfO!$A:$A,$A$30,AfO!$B:$B,$B34)/1000 -> 126.87121 | I34: =SUMIFS(AfO!J:J,AfO!$A:$A,$A$30,AfO!$B:$B,$B34)/1000 -> 118.89551 | R34: =SUM(J34:Q34) -> 0 | S34: =R34+I34 -> 118.89551 | T34: =(((I34/C34))^(1/5))-1 -> 0.19460667 | U34: =(((S34/I34))^(1/5))-1 -> 0
B35: Tea & Coffee | C35: =SUMIFS(AfO!D:D,AfO!$A:$A,$A$30,AfO!$B:$B,$B35)/1000 -> 0.03578134 | D35: =SUMIFS(AfO!E:E,AfO!$A:$A,$A$30,AfO!$B:$B,$B35)/1000 -> 0.07954173 | E35: =SUMIFS(AfO!F:F,AfO!$A:$A,$A$30,AfO!$B:$B,$B35)/1000 -> 0.12069796 | F35: =SUMIFS(AfO!G:G,AfO!$A:$A,$A$30,AfO!$B:$B,$B35)/1000 -> 0.14608294 | G35: =SUMIFS(AfO!H:H,AfO!$A:$A,$A$30,AfO!$B:$B,$B35)/1000 -> 0.77731622 | H35: =SUMIFS(AfO!I:I,AfO!$A:$A,$A$30,AfO!$B:$B,$B35)/1000 -> 1.4124798 | I35: =SUMIFS(AfO!J:J,AfO!$A:$A,$A$30,AfO!$B:$B,$B35)/1000 -> 3.9496711 | R35: =SUM(J35:Q35) -> 0 | S35: =R35+I35 -> 3.9496711 | T35: =(((I35/C35))^(1/5))-1 -> 1.5620103 | U35: =(((S35/I35))^(1/5))-1 -> 0
B36: Non-Alc. Beverages | C36: =SUM(C33:C35) -> 82.550445 | D36: =SUM(D33:D35) -> 89.230607 | E36: =SUM(E33:E35) -> 126.52523 | F36: =SUM(F33:F35) -> 162.2034 | G36: =SUM(G33:G35) -> 177.53488 | H36: =SUM(H33:H35) -> 215.2532 | I36: =SUM(I33:I35) -> 210.50253 | R36: =SUM(J36:Q36) -> 0 | S36: =R36+I36 -> 210.50253 | T36: =(((I36/C36))^(1/5))-1 -> 0.20588969 | U36: =(((S36/I36))^(1/5))-1 -> 0
A37: MEA | B37: Result | C37: =SUMIFS(AfO!D:D,AfO!$A:$A,$A$30,AfO!$B:$B,$B37)/1000 -> 146.25187 | D37: =SUMIFS(AfO!E:E,AfO!$A:$A,$A$30,AfO!$B:$B,$B37)/1000 -> 160.10378 | E37: =SUMIFS(AfO!F:F,AfO!$A:$A,$A$30,AfO!$B:$B,$B37)/1000 -> 200.5086 | F37: =SUMIFS(AfO!G:G,AfO!$A:$A,$A$30,AfO!$B:$B,$B37)/1000 -> 269.63334 | G37: =SUMIFS(AfO!H:H,AfO!$A:$A,$A$30,AfO!$B:$B,$B37)/1000 -> 288.60083 | H37: =SUMIFS(AfO!I:I,AfO!$A:$A,$A$30,AfO!$B:$B,$B37)/1000 -> 350.2815 | I37: =SUMIFS(AfO!J:J,AfO!$A:$A,$A$30,AfO!$B:$B,$B37)/1000 -> 340.30114 | R37: =SUM(J37:Q37) -> 0 | S37: =R37+I37 -> 340.30114 | T37: =(((I37/C37))^(1/5))-1 -> 0.18400188 | U37: =(((S37/I37))^(1/5))-1 -> 0
A38: TIP | B38: Brewery | C38: =SUMIFS(AfO!D:D,AfO!$A:$A,$A$38,AfO!$B:$B,$B38)/1000 -> 0.11018411 | D38: =SUMIFS(AfO!E:E,AfO!$A:$A,$A$38,AfO!$B:$B,$B38)/1000 -> 0.23603634 | E38: =SUMIFS(AfO!F:F,AfO!$A:$A,$A$38,AfO!$B:$B,$B38)/1000 -> 0.20331586 | F38: =SUMIFS(AfO!G:G,AfO!$A:$A,$A$38,AfO!$B:$B,$B38)/1000 -> 0.24843991 | G38: =SUMIFS(AfO!H:H,AfO!$A:$A,$A$38,AfO!$B:$B,$B38)/1000 -> 0.25705306 | H38: =SUMIFS(AfO!I:I,AfO!$A:$A,$A$38,AfO!$B:$B,$B38)/1000 -> 0.46552909 | I38: =SUMIFS(AfO!J:J,AfO!$A:$A,$A$38,AfO!$B:$B,$B38)/1000 -> 0.27165275 | R38: =SUM(J38:Q38) -> 0 | S38: =R38+I38 -> 0.27165275 | T38: =(((I38/C38))^(1/5))-1 -> 0.19778544 | U38: =(((S38/I38))^(1/5))-1 -> 0
B39: Cider, Wine & Spirit | C39: =SUMIFS(AfO!D:D,AfO!$A:$A,$A$38,AfO!$B:$B,$B39)/1000 -> 1.4041965 | D39: =SUMIFS(AfO!E:E,AfO!$A:$A,$A$38,AfO!$B:$B,$B39)/1000 -> 0.43151864 | E39: =SUMIFS(AfO!F:F,AfO!$A:$A,$A$38,AfO!$B:$B,$B39)/1000 -> 0.84039156 | F39: =SUMIFS(AfO!G:G,AfO!$A:$A,$A$38,AfO!$B:$B,$B39)/1000 -> 1.3543862 | G39: =SUMIFS(AfO!H:H,AfO!$A:$A,$A$38,AfO!$B:$B,$B39)/1000 -> 1.4115636 | H39: =SUMIFS(AfO!I:I,AfO!$A:$A,$A$38,AfO!$B:$B,$B39)/1000 -> 1.5981615 | I39: =SUMIFS(AfO!J:J,AfO!$A:$A,$A$38,AfO!$B:$B,$B39)/1000 -> 1.2010816 | R39: =SUM(J39:Q39) -> 0 | S39: =R39+I39 -> 1.2010816 | T39: =(((I39/C39))^(1/5))-1 -> -0.030765366 | U39: =(((S39/I39))^(1/5))-1 -> 0
B40: Alc. Beverages | C40: =SUM(C38:C39) -> 1.5143806 | D40: =SUM(D38:D39) -> 0.66755498 | E40: =SUM(E38:E39) -> 1.0437074 | F40: =SUM(F38:F39) -> 1.6028261 | G40: =SUM(G38:G39) -> 1.6686167 | H40: =SUM(H38:H39) -> 2.0636906 | I40: =SUM(I38:I39) -> 1.4727343 | R40: =SUM(J40:Q40) -> 0 | S40: =R40+I40 -> 1.4727343 | T40: =(((I40/C40))^(1/5))-1 -> -0.005561626 | U40: =(((S40/I40))^(1/5))-1 -> 0
B41: Juice & Juice Drink | C41: =SUMIFS(AfO!D:D,AfO!$A:$A,$A$38,AfO!$B:$B,$B41)/1000 -> 25.004953 | D41: =SUMIFS(AfO!E:E,AfO!$A:$A,$A$38,AfO!$B:$B,$B41)/1000 -> 29.108342 | E41: =SUMIFS(AfO!F:F,AfO!$A:$A,$A$38,AfO!$B:$B,$B41)/1000 -> 29.574215 | F41: =SUMIFS(AfO!G:G,AfO!$A:$A,$A$38,AfO!$B:$B,$B41)/1000 -> 32.094491 | G41: =SUMIFS(AfO!H:H,AfO!$A:$A,$A$38,AfO!$B:$B,$B41)/1000 -> 36.498247 | H41: =SUMIFS(AfO!I:I,AfO!$A:$A,$A$38,AfO!$B:$B,$B41)/1000 -> 47.849936 | I41: =SUMIFS(AfO!J:J,AfO!$A:$A,$A$38,AfO!$B:$B,$B41)/1000 -> 40.561618 | R41: =SUM(J41:Q41) -> 0 | S41: =R41+I41 -> 40.561618 | T41: =(((I41/C41))^(1/5))-1 -> 0.10158457 | U41: =(((S41/I41))^(1/5))-1 -> 0
...

Sheet 1 - X5 Template Print Out
J2: X5 Targets
A3: Gross Sales ['mio. €] | J3: B2C Applications Beverage
A4: Region | B4: Market Segments L2 | C4: FY 2019 | D4: FY 2020 | E4: FY 2021 | F4: FY 2022 | G4: FY 2023 | H4: BUD 2024 | I4: RunRate 2024 | J4: Beer & Malt Bev. | K4: Cider, Wine, Spirits | L4: Instant & Dry Bev. | M4: Juices & Juice Drnks | N4: Soft Drinks & Waters | O4: Sports,Ener,FuncDrnk | P4: Syrups | Q4: Tea & Coffee Drinks | R4: X5 Growth | S4: FY 2029 (est.) | T4: CAGR '19 - '24 | U4: CAGR '24 - '29
C5: *mio. € | D5: *mio. € | E5: *mio. € | F5: *mio. € | G5: *mio. € | H5: *mio. € | I5: *mio. € | J5: *mio. € | K5: *mio. € | L5: *mio. € | M5: *mio. € | N5: *mio. € | O5: *mio. € | P5: *mio. € | Q5: *mio. € | R5: *mio. € | S5: *mio. € | T5: % | U5: %
A6: Group | B6: Brewery | C6: =SUMIFS(AfO!D:D,AfO!$A:$A,$A$6,AfO!$B:$B,$B6)/1000 -> 165.75023 | D6: =SUMIFS(AfO!E:E,AfO!$A:$A,$A$6,AfO!$B:$B,$B6)/1000 -> 181.95778 | E6: =SUMIFS(AfO!F:F,AfO!$A:$A,$A$6,AfO!$B:$B,$B6)/1000 -> 226.90863 | F6: =SUMIFS(AfO!G:G,AfO!$A:$A,$A$6,AfO!$B:$B,$B6)/1000 -> 276.0359 | G6: =SUMIFS(AfO!H:H,AfO!$A:$A,$A$6,AfO!$B:$B,$B6)/1000 -> 280.99441 | H6: =SUMIFS(AfO!I:I,AfO!$A:$A,$A$6,AfO!$B:$B,$B6)/1000 -> 315.70569 | I6: =SUMIFS(AfO!J:J,AfO!$A:$A,$A$6,AfO!$B:$B,$B6)/1000 -> 305.72125 | J6: 75 | K6: 55 | L6: 5 | M6: 15 | N6: 5 | O6: 35 | P6: 3 | Q6: 3 | R6: =SUM(J6:Q6) -> 196 | S6: =R6+I6 -> 501.72125 | T6: =(((I6/C6))^(1/5))-1 -> 0.13024943 | U6: =(((S6/I6))^(1/5))-1 -> 0.10414821
B7: Cider, Wine & Spirit | C7: =SUMIFS(AfO!D:D,AfO!$A:$A,$A$6,AfO!$B:$B,$B7)/1000 -> 66.58099 | D7: =SUMIFS(AfO!E:E,AfO!$A:$A,$A$6,AfO!$B:$B,$B7)/1000 -> 67.226292 | E7: =SUMIFS(AfO!F:F,AfO!$A:$A,$A$6,AfO!$B:$B,$B7)/1000 -> 80.465685 | F7: =SUMIFS(AfO!G:G,AfO!$A:$A,$A$6,AfO!$B:$B,$B7)/1000 -> 98.636943 | G7: =SUMIFS(AfO!H:H,AfO!$A:$A,$A$6,AfO!$B:$B,$B7)/1000 -> 97.626815 | H7: =SUMIFS(AfO!I:I,AfO!$A:$A,$A$6,AfO!$B:$B,$B7)/1000 -> 108.22972 | I7: =SUMIFS(AfO!J:J,AfO!$A:$A,$A$6,AfO!$B:$B,$B7)/1000 -> 101.28411 | J7: 5 | K7: 47 | L7: -0.00997653 | M7: 5 | N7: 2 | O7: 5 | P7: 3 | Q7: 3 | R7: =SUM(J7:Q7) -> 69.990023 | S7: =R7+I7 -> 171.27413 | T7: =(((I7/C7))^(1/5))-1 -> 0.087522398 | U7: =(((S7/I7))^(1/5))-1 -> 0.11078522
B8: Alc. Beverages | C8: =SUM(C6:C7) -> 232.33122 | D8: =SUM(D6:D7) -> 249.18407 | E8: =SUM(E6:E7) -> 307.37431 | F8: =SUM(F6:F7) -> 374.67284 | G8: =SUM(G6:G7) -> 378.62123 | H8: =SUM(H6:H7) -> 423.93541 | I8: =SUM(I6:I7) -> 407.00536 | J8: =SUM(J6:J7) -> 80 | ... Q8: =SUM(Q6:Q7) -> 6 | R8: =SUM(J8:Q8) -> 265.99002 | S8: =R8+I8 -> 672.99538 | T8: =(((I8/C8))^(1/5))-1 -> 0.11866103 | U8: =(((S8/I8))^(1/5))-1 -> 0.10581478
B9: Juice & Juice Drink | C9: =SUMIFS(AfO!D:D,AfO!$A:$A,$A$6,AfO!$B:$B,$B9)/1000 -> 448.51278 | D9: =SUMIFS(AfO!E:E,AfO!$A:$A,$A$6,AfO!$B:$B,$B9)/1000 -> 450.56219 | E9: =SUMIFS(AfO!F:F,AfO!$A:$A,$A$6,AfO!$B:$B,$B9)/1000 -> 524.17919 | F9: =SUMIFS(AfO!G:G,AfO!$A:$A,$A$6,AfO!$B:$B,$B9)/1000 -> 718.52288 | G9: =SUMIFS(AfO!H:H,AfO!$A:$A,$A$6,AfO!$B:$B,$B9)/1000 -> 752.9857 | H9: =SUMIFS(AfO!I:I,AfO!$A:$A,$A$6,AfO!$B:$B,$B9)/1000 -> 839.00331 | I9: =SUMIFS(AfO!J:J,AfO!$A:$A,$A$6,AfO!$B:$B,$B9)/1000 -> 852.00248 | J9: 0 | K9: 4.4299278 | L9: 11.004806 | M9: 130.26788 | N9: 47.250378 | O9: 27.748372 | P9: 15.902551 | Q9: 2 | R9: =SUM(J9:Q9) -> 238.60391 | S9: =R9+I9 -> 1090.6064 | T9: =(((I9/C9))^(1/5))-1 -> 0.13692864 | U9: =(((S9/I9))^(1/5))-1 -> 0.050619449
B10: Soft Drink | C10: =SUMIFS(AfO!D:D,AfO!$A:$A,$A$6,AfO!$B:$B,$B10)/1000 -> 533.04683 | D10: =SUMIFS(AfO!E:E,AfO!$A:$A,$A$6,AfO!$B:$B,$B10)/1000 -> 537.17507 | E10: =SUMIFS(AfO!F:F,AfO!$A:$A,$A$6,AfO!$B:$B,$B10)/1000 -> 639.48888 | F10: =SUMIFS(AfO!G:G,AfO!$A:$A,$A$6,AfO!$B:$B,$B10)/1000 -> 765.27568 | G10: =SUMIFS(AfO!H:H,AfO!$A:$A,$A$6,AfO!$B:$B,$B10)/1000 -> 818.63761 | H10: =SUMIFS(AfO!I:I,AfO!$A:$A,$A$6,AfO!$B:$B,$B10)/1000 -> 913.72867 | I10: =SUMIFS(AfO!J:J,AfO!$A:$A,$A$6,AfO!$B:$B,$B10)/1000 -> 904.80327 | J10: 0 | K10: 8.4203921 | L10: 6.1562218 | M10: 0 | N10: 220 | O10: 139.80983 | P10: 10.510406 | Q10: 5.8121645 | R10: =SUM(J10:Q10) -> 390.70901 | S10: =R10+I10 -> 1295.5123 | T10: =(((I10/C10))^(1/5))-1 -> 0.1116236 | U10: =(((S10/I10))^(1/5))-1 -> 0.074428389
B11: Tea & Coffee | C11: =SUMIFS(AfO!D:D,AfO!$A:$A,$A$6,AfO!$B:$B,$B11)/1000 -> 17.862578 | D11: =SUMIFS(AfO!E:E,AfO!$A:$A,$A$6,AfO!$B:$B,$B11)/1000 -> 13.869647 | E11: =SUMIFS(AfO!F:F,AfO!$A:$A,$A$6,AfO!$B:$B,$B11)/1000 -> 26.047573 | F11: =SUMIFS(AfO!G:G,AfO!$A:$A,$A$6,AfO!$B:$B,$B11)/1000 -> 19.449724 | G11: =SUMIFS(AfO!H:H,AfO!$A:$A,$A$6,AfO!$B:$B,$B11)/1000 -> 43.366981 | H11: =SUMIFS(AfO!I:I,AfO!$A:$A,$A$6,AfO!$B:$B,$B11)/1000 -> 43.8466 | I11: =SUMIFS(AfO!J:J,AfO!$A:$A,$A$6,AfO!$B:$B,$B11)/1000 -> 49.662591 | J11: 0 | K11: 3.6781622 | L11: 0 | M11: 0.1267017 | N11: 3.2551118 | O11: 0.96742954 | P11: 0 | Q11: 50 | R11: =SUM(J11:Q11) -> 58.027405 | S11: =R11+I11 -> 107.69 | T11: =(((I11/C11))^(1/5))-1 -> 0.22692226 | U11: =(((S11/I11))^(1/5))-1 -> 0.16742556
B12: Non-Alc. Beverages | C12: =SUM(C9:C11) -> 999.42219 | D12: =SUM(D9:D11) -> 1001.6069 | E12: =SUM(E9:E11) -> 1189.7157 | F12: =SUM(F9:F11) -> 1503.2483 | G12: =SUM(G9:G11) -> 1614.9903 | H12: =SUM(H9:H11) -> 1796.5786 | I12: =SUM(I9:I11) -> 1806.4683 | J12: =SUM(J9:J11) -> 0 | ... Q12: =SUM(Q9:Q11) -> 57.812164 | R12: =SUM(J12:Q12) -> 687.34033 | S12: =R12+I12 -> 2493.8087 | T12: =(((I12/C12))^(1/5))-1 -> 0.12568343 | U12: =(((S12/I12))^(1/5))-1 -> 0.066612221
A13: Overall | B13: Result | C13: =SUMIFS(AfO!D:D,AfO!$A:$A,$A$6,AfO!$B:$B,$B13)/1000 -> 1740.6113 | D13: =SUMIFS(AfO!E:E,AfO!$A:$A,$A$6,AfO!$B:$B,$B13)/1000 -> 1789.7402 | E13: =SUMIFS(AfO!F:F,AfO!$A:$A,$A$6,AfO!$B:$B,$B13)/1000 -> 2161.4626 | F13: =SUMIFS(AfO!G:G,AfO!$A:$A,$A$6,AfO!$B:$B,$B13)/1000 -> 2722.0949 | G13: =SUMIFS(AfO!H:H,AfO!$A:$A,$A$6,AfO!$B:$B,$B13)/1000 -> 2872.4323 | H13: =SUMIFS(AfO!I:I,AfO!$A:$A,$A$6,AfO!$B:$B,$B13)/1000 -> 3372.8648 | I13: =SUMIFS(AfO!J:J,AfO!$A:$A,$A$6,AfO!$B:$B,$B13)/1000 -> 3266.363 | J13: =SUM(J12,J8) -> 80 | K13: =SUM(K12,K8) -> 118.52848 | L13: =SUM(L12,L8) -> 22.151051 | M13: =SUM(M12,M8) -> 150.39458 | N13: =SUM(N12,N8) -> 277.50549 | O13: =SUM(O12,O8) -> 208.52563 | P13: =SUM(P12,P8) -> 32.412957 | Q13: =SUM(Q12,Q8) -> 63.812164 | R13: =SUM(J13:Q13) -> 953.33036 | S13: =R13+I13 -> 4219.6934 | T13: =(((I13/C13))^(1/5))-1 -> 0.1341553 | U13: =(((S13/I13))^(1/5))-1 -> 0.052551341
A14: EUR | B14: Brewery | C14: =SUMIFS(AfO!D:D,AfO!$A:$A,$A$14,AfO!$B:$B,$B14)/1000 -> 97.999654 | D14: =SUMIFS(AfO!E:E,AfO!$A:$A,$A$14,AfO!$B:$B,$B14)/1000 -> 100.43935 | E14: =SUMIFS(AfO!F:F,AfO!$A:$A,$A$14,AfO!$B:$B,$B14)/1000 -> 110.24313 | F14: =SUMIFS(AfO!G:G,AfO!$A:$A,$A$14,AfO!$B:$B,$B14)/1000 -> 122.20181 | G14: =SUMIFS(AfO!H:H,AfO!$A:$A,$A$14,AfO!$B:$B,$B14)/1000 -> 121.60873 | H14: =SUMIFS(AfO!I:I,AfO!$A:$A,$A$14,AfO!$B:$B,$B14)/1000 -> 140.2787 | I14: =SUMIFS(AfO!J:J,AfO!$A:$A,$A$14,AfO!$B:$B,$B14)/1000 -> 150.31435 | R14: =SUM(J14:Q14) -> 0 | S14: =R14+I14 -> 150.31435 | T14: =(((I14/C14))^(1/5))-1 -> 0.089319259 | U14: =(((S14/I14))^(1/5))-1 -> 0
B15: Cider, Wine & Spirit | C15: =SUMIFS(AfO!D:D,AfO!$A:$A,$A$14,AfO!$B:$B,$B15)/1000 -> 52.067942 | D15: =SUMIFS(AfO!E:E,AfO!$A:$A,$A$14,AfO!$B:$B,$B15)/1000 -> 54.05732 | E15: =SUMIFS(AfO!F:F,AfO!$A:$A,$A$14,AfO!$B:$B,$B15)/1000 -> 56.933623 | F15: =SUMIFS(AfO!G:G,AfO!$A:$A,$A$14,AfO!$B:$B,$B15)/1000 -> 68.938936 | G15: =SUMIFS(AfO!H:H,AfO!$A:$A,$A$14,AfO!$B:$B,$B15)/1000 -> 66.889477 | H15: =SUMIFS(AfO!I:I,AfO!$A:$A,$A$14,AfO!$B:$B,$B15)/1000 -> 73.8833 | I15: =SUMIFS(AfO!J:J,AfO!$A:$A,$A$14,AfO!$B:$B,$B15)/1000 -> 67.038592 | R15: =SUM(J15:Q15) -> 0 | S15: =R15+I15 -> 67.038592 | T15: =(((I15/C15))^(1/5))-1 -> 0.051842934 | U15: =(((S15/I15))^(1/5))-1 -> 0
B16: Alc. Beverages | C16: =SUM(C14:C15) -> 150.0676 | D16: =SUM(D14:D15) -> 154.49667 | E16: =SUM(E14:E15) -> 167.17675 | F16: =SUM(F14:F15) -> 191.14074 | G16: =SUM(G14:G15) -> 188.49821 | H16: =SUM(H14:H15) -> 214.162 | I16: =SUM(I14:I15) -> 217.35295 | R16: =SUM(J16:Q16) -> 0 | S16: =R16+I16 -> 217.35295 | T16: =(((I16/C16))^(1/5))-1 -> 0.076900852 | U16: =(((S16/I16))^(1/5))-1 -> 0
B17: Juice & Juice Drink | C17: =SUMIFS(AfO!D:D,AfO!$A:$A,$A$14,AfO!$B:$B,$B17)/1000 -> 261.99452 | D17: =SUMIFS(AfO!E:E,AfO!$A:$A,$A$14,AfO!$B:$B,$B17)/1000 -> 278.46378 | E17: =SUMIFS(AfO!F:F,AfO!$A:$A,$A$14,AfO!$B:$B,$B17)/1000 -> 299.57684 | F17: =SUMIFS(AfO!G:G,AfO!$A:$A,$A$14,AfO!$B:$B,$B17)/1000 -> 365.92302 | G17: =SUMIFS(AfO!H:H,AfO!$A:$A,$A$14,AfO!$B:$B,$B17)/1000 -> 376.34058 | H17: =SUMIFS(AfO!I:I,AfO!$A:$A,$A$14,AfO!$B:$B,$B17)/1000 -> 405.59679 | I17: =SUMIFS(AfO!J:J,AfO!$A:$A,$A$14,AfO!$B:$B,$B17)/1000 -> 429.72051 | R17: =SUM(J17:Q17) -> 0 | S17: =R17+I17 -> 429.72051 | T17: =(((I17/C17))^(1/5))-1 -> 0.10402466 | U17: =(((S17/I17))^(1/5))-1 -> 0
B18: Soft Drink | C18: =SUMIFS(AfO!D:D,AfO!$A:$A,$A$14,AfO!$B:$B,$B18)/1000 -> 343.01031 | D18: =SUMIFS(AfO!E:E,AfO!$A:$A,$A$14,AfO!$B:$B,$B18)/1000 -> 333.31249 | E18: =SUMIFS(AfO!F:F,AfO!$A:$A,$A$14,AfO!$B:$B,$B18)/1000 -> 349.99055 | F18: =SUMIFS(AfO!G:G,AfO!$A:$A,$A$14,AfO!$B:$B,$B18)/1000 -> 390.58592 | G18: =SUMIFS(AfO!H:H,AfO!$A:$A,$A$14,AfO!$B:$B,$B18)/1000 -> 423.03394 | H18: =SUMIFS(AfO!I:I,AfO!$A:$A,$A$14,AfO!$B:$B,$B18)/1000 -> 465.71905 | I18: =SUMIFS(AfO!J:J,AfO!$A:$A,$A$14,AfO!$B:$B,$B18)/1000 -> 469.60336 | R18: =SUM(J18:Q18) -> 0 | S18: =R18+I18 -> 469.60336 | T18: =(((I18/C18))^(1/5))-1 -> 0.064841094 | U18: =(((S18/I18))^(1/5))-1 -> 0
B19: Tea & Coffee | C19: =SUMIFS(AfO!D:D,AfO!$A:$A,$A$14,AfO!$B:$B,$B19)/1000 -> 5.610625 | D19: =SUMIFS(AfO!E:E,AfO!$A:$A,$A$14,AfO!$B:$B,$B19)/1000 -> 6.6683898 | E19: =SUMIFS(AfO!F:F,AfO!$A:$A,$A$14,AfO!$B:$B,$B19)/1000 -> 8.3057916 | F19: =SUMIFS(AfO!G:G,AfO!$A:$A,$A$14,AfO!$B:$B,$B19)/1000 -> 12.354032 | G19: =SUMIFS(AfO!H:H,AfO!$A:$A,$A$14,AfO!$B:$B,$B19)/1000 -> 34.76055 | H19: =SUMIFS(AfO!I:I,AfO!$A:$A,$A$14,AfO!$B:$B,$B19)/1000 -> 21.997327 | I19: =SUMIFS(AfO!J:J,AfO!$A:$A,$A$14,AfO!$B:$B,$B19)/1000 -> 28.611594 | R19: =SUM(J19:Q19) -> 0 | S19: =R19+I19 -> 28.611594 | T19: =(((I19/C19))^(1/5))-1 -> 0.38517984 | U19: =(((S19/I19))^(1/5))-1 -> 0
B20: Non-Alc. Beverages | C20: =SUM(C17:C19) -> 610.61546 | D20: =SUM(D17:D19) -> 618.44466 | E20: =SUM(E17:E19) -> 657.87318 | F20: =SUM(F17:F19) -> 768.86297 | G20: =SUM(G17:G19) -> 834.13507 | H20: =SUM(H17:H19) -> 893.31317 | I20: =SUM(I17:I19) -> 927.93546 | R20: =SUM(J20:Q20) -> 0 | S20: =R20+I20 -> 927.93546 | T20: =(((I20/C20))^(1/5))-1 -> 0.08730152 | U20: =(((S20/I20))^(1/5))-1 -> 0
A21: EUR | B21: Result | C21: =SUMIFS(AfO!D:D,AfO!$A:$A,$A$14,AfO!$B:$B,$B21)/1000 -> 1002.3255 | D21: =SUMIFS(AfO!E:E,AfO!$A:$A,$A$14,AfO!$B:$B,$B21)/1000 -> 1027.1281 | E21: =SUMIFS(AfO!F:F,AfO!$A:$A,$A$14,AfO!$B:$B,$B21)/1000 -> 1132.78 | F21: =SUMIFS(AfO!G:G,AfO!$A:$A,$A$14,AfO!$B:$B,$B21)/1000 -> 1334.6647 | G21: =SUMIFS(AfO!H:H,AfO!$A:$A,$A$14,AfO!$B:$B,$B21)/1000 -> 1427.9009 | H21: =SUMIFS(AfO!I:I,AfO!$A:$A,$A$14,AfO!$B:$B,$B21)/1000 -> 1623.8557 | I21: =SUMIFS(AfO!J:J,AfO!$A:$A,$A$14,AfO!$B:$B,$B21)/1000 -> 1658.2837 | R21: =SUM(J21:Q21) -> 0 | S21: =R21+I21 -> 1658.2837 | T21: =(((I21/C21))^(1/5))-1 -> 0.10593604 | U21: =(((S21/I21))^(1/5))-1 -> 0
A22: CIS | B22: Brewery | C22: =SUMIFS(AfO!D:D,AfO!$A:$A,$A$22,AfO!$B:$B,$B22)/1000 -> 27.557979 | D22: =SUMIFS(AfO!E:E,AfO!$A:$A,$A$22,AfO!$B:$B,$B22)/1000 -> 34.026537 | E22: =SUMIFS(AfO!F:F,AfO!$A:$A,$A$22,AfO!$B:$B,$B22)/1000 -> 40.808168 | F22: =SUMIFS(AfO!G:G,AfO!$A:$A,$A$22,AfO!$B:$B,$B22)/1000 -> 59.492633 | G22: =SUMIFS(AfO!H:H,AfO!$A:$A,$A$22,AfO!$B:$B,$B22)/1000 -> 78.140682 | H22: =SUMIFS(AfO!I:I,AfO!$A:$A,$A$22,AfO!$B:$B,$B22)/1000 -> 83.286073 | I22: =SUMIFS(AfO!J:J,AfO!$A:$A,$A$22,AfO!$B:$B,$B22)/1000 -> 81.515774 | R22: =SUM(J22:Q22) -> 0 | S22: =R22+I22 -> 81.515774 | T22: =(((I22/C22))^(1/5))-1 -> 0.24222098 | U22: =(((S22/I22))^(1/5))-1 -> 0
B23: Cider, Wine & Spirit | C23: =SUMIFS(AfO!D:D,AfO!$A:$A,$A$22,AfO!$B:$B,$B23)/1000 -> 4.9480509 | D23: =SUMIFS(AfO!E:E,AfO!$A:$A,$A$22,AfO!$B:$B,$B23)/1000 -> 4.9606367 | E23: =SUMIFS(AfO!F:F,AfO!$A:$A,$A$22,AfO!$B:$B,$B23)/1000 -> 6.6925095 | F23: =SUMIFS(AfO!G:G,AfO!$A:$A,$A$22,AfO!$B:$B,$B23)/1000 -> 8.8634774 | G23: =SUMIFS(AfO!H:H,AfO!$A:$A,$A$22,AfO!$B:$B,$B23)/1000 -> 10.46572 | H23: =SUMIFS(AfO!I:I,AfO!$A:$A,$A$22,AfO!$B:$B,$B23)/1000 -> 10.913152 | I23: =SUMIFS(AfO!J:J,AfO!$A:$A,$A$22,AfO!$B:$B,$B23)/1000 -> 10.162663 | R23: =SUM(J23:Q23) -> 0 | S23: =R23+I23 -> 10.162663 | T23: =(((I23/C23))^(1/5))-1 -> 0.15482099 | U23: =(((S23/I23))^(1/5))-1 -> 0
B24: Alc. Beverages | C24: =SUM(C22:C23) -> 32.50603 | D24: =SUM(D22:D23) -> 38.987173 | E24: =SUM(E22:E23) -> 47.500677 | F24: =SUM(F22:F23) -> 68.356111 | G24: =SUM(G22:G23) -> 88.606403 | H24: =SUM(H22:H23) -> 94.199225 | I24: =SUM(I22:I23) -> 91.678436 | R24: =SUM(J24:Q24) -> 0 | S24: =R24+I24 -> 91.678436 | T24: =(((I24/C24))^(1/5))-1 -> 0.2304406 | U24: =(((S24/I24))^(1/5))-1 -> 0
B25: Juice & Juice Drink | C25: =SUMIFS(AfO!D:D,AfO!$A:$A,$A$22,AfO!$B:$B,$B25)/1000 -> 24.904139 | D25: =SUMIFS(AfO!E:E,AfO!$A:$A,$A$22,AfO!$B:$B,$B25)/1000 -> 25.904293 | E25: =SUMIFS(AfO!F:F,AfO!$A:$A,$A$22,AfO!$B:$B,$B25)/1000 -> 40.460769 | F25: =SUMIFS(AfO!G:G,AfO!$A:$A,$A$22,AfO!$B:$B,$B25)/1000 -> 47.809997 | G25: =SUMIFS(AfO!H:H,AfO!$A:$A,$A$22,AfO!$B:$B,$B25)/1000 -> 47.678844 | H25: =SUMIFS(AfO!I:I,AfO!$A:$A,$A$22,AfO!$B:$B,$B25)/1000 -> 48.234836 | I25: =SUMIFS(AfO!J:J,AfO!$A:$A,$A$22,AfO!$B:$B,$B25)/1000 -> 49.061505 | R25: =SUM(J25:Q25) -> 0 | S25: =R25+I25 -> 49.061505 | T25: =(((I25/C25))^(1/5))-1 -> 0.14523303 | U25: =(((S25/I25))^(1/5))-1 -> 0
B26: Soft Drink | C26: =SUMIFS(AfO!D:D,AfO!$A:$A,$A$22,AfO!$B:$B,$B26)/1000 -> 50.91124 | D26: =SUMIFS(AfO!E:E,AfO!$A:$A,$A$22,AfO!$B:$B,$B26)/1000 -> 51.96288 | E26: =SUMIFS(AfO!F:F,AfO!$A:$A,$A$22,AfO!$B:$B,$B26)/1000 -> 60.896476 | F26: =SUMIFS(AfO!G:G,AfO!$A:$A,$A$22,AfO!$B:$B,$B26)/1000 -> 88.767684 | G26: =SUMIFS(AfO!H:H,AfO!$A:$A,$A$22,AfO!$B:$B,$B26)/1000 -> 101.15826 | H26: =SUMIFS(AfO!I:I,AfO!$A:$A,$A$22,AfO!$B:$B,$B26)/1000 -> 107.84782 | I26: =SUMIFS(AfO!J:J,AfO!$A:$A,$A$22,AfO!$B:$B,$B26)/1000 -> 111.67105 | R26: =SUM(J26:Q26) -> 0 | S26: =R26+I26 -> 111.67105 | T26: =(((I26/C26))^(1/5))-1 -> 0.17010647 | U26: =(((S26/I26))^(1/5))-1 -> 0
B27: Tea & Coffee | C27: =SUMIFS(AfO!D:D,AfO!$A:$A,$A$22,AfO!$B:$B,$B27)/1000 -> 0.03437503 | D27: =SUMIFS(AfO!E:E,AfO!$A:$A,$A$22,AfO!$B:$B,$B27)/1000 -> 0.00562934 | E27: =SUMIFS(AfO!F:F,AfO!$A:$A,$A$22,AfO!$B:$B,$B27)/1000 -> 0.00759373 | F27: =SUMIFS(AfO!G:G,AfO!$A:$A,$A$22,AfO!$B:$B,$B27)/1000 -> 0.00245045 | G27: =SUMIFS(AfO!H:H,AfO!$A:$A,$A$22,AfO!$B:$B,$B27)/1000 -> 0.00267864 | H27: =SUMIFS(AfO!I:I,AfO!$A:$A,$A$22,AfO!$B:$B,$B27)/1000 -> 0.00279078 | I27: =SUMIFS(AfO!J:J,AfO!$A:$A,$A$22,AfO!$B:$B,$B27)/1000 -> 0.00251298 | R27: =SUM(J27:Q27) -> 0 | S27: =R27+I27 -> 0.00251298 | T27: =(((I27/C27))^(1/5))-1 -> -0.40736242 | U27: =(((S27/I27))^(1/5))-1 -> 0
B28: Non-Alc. Beverages | C28: =SUM(C25:C27) -> 75.849754 | D28: =SUM(D25:D27) -> 77.872802 | E28: =SUM(E25:E27) -> 101.36484 | F28: =SUM(F25:F27) -> 136.58013 | G28: =SUM(G25:G27) -> 148.83979 | H28: =SUM(H25:H27) -> 156.08544 | I28: =SUM(I25:I27) -> 160.73506 | R28: =SUM(J28:Q28) -> 0 | S28: =R28+I28 -> 160.73506 | T28: =(((I28/C28))^(1/5))-1 -> 0.16206732 | U28: =(((S28/I28))^(1/5))-1 -> 0
A29: CIS | B29: Result | C29: =SUMIFS(AfO!D:D,AfO!$A:$A,$A$22,AfO!$B:$B,$B29)/1000 -> 134.48379 | D29: =SUMIFS(AfO!E:E,AfO!$A:$A,$A$22,AfO!$B:$B,$B29)/1000 -> 153.57053 | E29: =SUMIFS(AfO!F:F,AfO!$A:$A,$A$22,AfO!$B:$B,$B29)/1000 -> 190.21406 | F29: =SUMIFS(AfO!G:G,AfO!$A:$A,$A$22,AfO!$B:$B,$B29)/1000 -> 254.85824 | G29: =SUMIFS(AfO!H:H,AfO!$A:$A,$A$22,AfO!$B:$B,$B29)/1000 -> 286.46813 | H29: =SUMIFS(AfO!I:I,AfO!$A:$A,$A$22,AfO!$B:$B,$B29)/1000 -> 303.1095 | I29: =SUMIFS(AfO!J:J,AfO!$A:$A,$A$22,AfO!$B:$B,$B29)/1000 -> 292.76585 | R29: =SUM(J29:Q29) -> 0 | S29: =R29+I29 -> 292.76585 | T29: =(((I29/C29))^(1/5))-1 -> 0.16834229 | U29: =(((S29/I29))^(1/5))-1 -> 0
A30: MEA | B30: Brewery | C30: =SUMIFS(AfO!D:D,AfO!$A:$A,$A$30,AfO!$B:$B,$B30)/1000 -> 10.025434 | D30: =SUMIFS(AfO!E:E,AfO!$A:$A,$A$30,AfO!$B:$B,$B30)/1000 -> 2.4862199 | E30: =SUMIFS(AfO!F:F,AfO!$A:$A,$A$30,AfO!$B:$B,$B30)/1000 -> 9.496856 | F30: =SUMIFS(AfO!G:G,AfO!$A:$A,$A$30,AfO!$B:$B,$B30)/1000 -> 16.853422 | G30: =SUMIFS(AfO!H:H,AfO!$A:$A,$A$30,AfO!$B:$B,$B30)/1000 -> 19.249253 | H30: =SUMIFS(AfO!I:I,AfO!$A:$A,$A$30,AfO!$B:$B,$B30)/1000 -> 20.831869 | I30: =SUMIFS(AfO!J:J,AfO!$A:$A,$A$30,AfO!$B:$B,$B30)/1000 -> 13.086355 | R30: =SUM(J30:Q30) -> 0 | S30: =R30+I30 -> 13.086355 | T30: =(((I30/C30))^(1/5))-1 -> 0.05473439 | U30: =(((S30/I30))^(1/5))-1 -> 0
B31: Cider, Wine & Spirit | C31: =SUMIFS(AfO!D:D,AfO!$A:$A,$A$30,AfO!$B:$B,$B31)/1000 -> 3.9762726 | D31: =SUMIFS(AfO!E:E,AfO!$A:$A,$A$30,AfO!$B:$B,$B31)/1000 -> 4.1155043 | E31: =SUMIFS(AfO!F:F,AfO!$A:$A,$A$30,AfO!$B:$B,$B31)/1000 -> 7.802599 | F31: =SUMIFS(AfO!G:G,AfO!$A:$A,$A$30,AfO!$B:$B,$B31)/1000 -> 9.965696 | G31: =SUMIFS(AfO!H:H,AfO!$A:$A,$A$30,AfO!$B:$B,$B31)/1000 -> 8.1696931 | H31: =SUMIFS(AfO!I:I,AfO!$A:$A,$A$30,AfO!$B:$B,$B31)/1000 -> 9.6389157 | I31: =SUMIFS(AfO!J:J,AfO!$A:$A,$A$30,AfO!$B:$B,$B31)/1000 -> 13.493692 | R31: =SUM(J31:Q31) -> 0 | S31: =R31+I31 -> 13.493692 | T31: =(((I31/C31))^(1/5))-1 -> 0.27682368 | U31: =(((S31/I31))^(1/5))-1 -> 0
B32: Alc. Beverages | C32: =SUM(C30:C31) -> 14.001706 | D32: =SUM(D30:D31) -> 6.6017241 | E32: =SUM(E30:E31) -> 17.299455 | F32: =SUM(F30:F31) -> 26.819118 | G32: =SUM(G30:G31) -> 27.418946 | H32: =SUM(H30:H31) -> 30.470784 | I32: =SUM(I30:I31) -> 26.580047 | R32: =SUM(J32:Q32) -> 0 | S32: =R32+I32 -> 26.580047 | T32: =(((I32/C32))^(1/5))-1 -> 0.13677616 | U32: =(((S32/I32))^(1/5))-1 -> 0
B33: Juice & Juice Drink | C33: =SUMIFS(AfO!D:D,AfO!$A:$A,$A$30,AfO!$B:$B,$B33)/1000 -> 33.644841 | D33: =SUMIFS(AfO!E:E,AfO!$A:$A,$A$30,AfO!$B:$B,$B33)/1000 -> 40.316276 | E33: =SUMIFS(AfO!F:F,AfO!$A:$A,$A$30,AfO!$B:$B,$B33)/1000 -> 47.183211 | F33: =SUMIFS(AfO!G:G,AfO!$A:$A,$A$30,AfO!$B:$B,$B33)/1000 -> 60.248435 | G33: =SUMIFS(AfO!H:H,AfO!$A:$A,$A$30,AfO!$B:$B,$B33)/1000 -> 76.822222 | H33: =SUMIFS(AfO!I:I,AfO!$A:$A,$A$30,AfO!$B:$B,$B33)/1000 -> 86.969503 | I33: =SUMIFS(AfO!J:J,AfO!$A:$A,$A$30,AfO!$B:$B,$B33)/1000 -> 87.657356 | R33: =SUM(J33:Q33) -> 0 | S33: =R33+I33 -> 87.657356 | T33: =(((I33/C33))^(1/5))-1 -> 0.21108319 | U33: =(((S33/I33))^(1/5))-1 -> 0
B34: Soft Drink | C34: =SUMIFS(AfO!D:D,AfO!$A:$A,$A$30,AfO!$B:$B,$B34)/1000 -> 48.869823 | D34: =SUMIFS(AfO!E:E,AfO!$A:$A,$A$30,AfO!$B:$B,$B34)/1000 -> 48.83479 | E34: =SUMIFS(AfO!F:F,AfO!$A:$A,$A$30,AfO!$B:$B,$B34)/1000 -> 79.221321 | F34: =SUMIFS(AfO!G:G,AfO!$A:$A,$A$30,AfO!$B:$B,$B34)/1000 -> 101.80888 | G34: =SUMIFS(AfO!H:H,AfO!$A:$A,$A$30,AfO!$B:$B,$B34)/1000 -> 99.93534 | H34: =SUMIFS(AfO!I:I,AfO!$A:$A,$A$30,AfO!$B:$B,$B34)/1000 -> 126.87121 | I34: =SUMIFS(AfO!J:J,AfO!$A:$A,$A$30,AfO!$B:$B,$B34)/1000 -> 118.89551 | R34: =SUM(J34:Q34) -> 0 | S34: =R34+I34 -> 118.89551 | T34: =(((I34/C34))^(1/5))-1 -> 0.19460667 | U34: =(((S34/I34))^(1/5))-1 -> 0
B35: Tea & Coffee | C35: =SUMIFS(AfO!D:D,AfO!$A:$A,$A$30,AfO!$B:$B,$B35)/1000 -> 0.03578134 | D35: =SUMIFS(AfO!E:E,AfO!$A:$A,$A$30,AfO!$B:$B,$B35)/1000 -> 0.07954173 | E35: =SUMIFS(AfO!F:F,AfO!$A:$A,$A$30,AfO!$B:$B,$B35)/1000 -> 0.12069796 | F35: =SUMIFS(AfO!G:G,AfO!$A:$A,$A$30,AfO!$B:$B,$B35)/1000 -> 0.14608294 | G35: =SUMIFS(AfO!H:H,AfO!$A:$A,$A$30,AfO!$B:$B,$B35)/1000 -> 0.77731622 | H35: =SUMIFS(AfO!I:I,AfO!$A:$A,$A$30,AfO!$B:$B,$B35)/1000 -> 1.4124798 | I35: =SUMIFS(AfO!J:J,AfO!$A:$A,$A$30,AfO!$B:$B,$B35)/1000 -> 3.9496711 | R35: =SUM(J35:Q35) -> 0 | S35: =R35+I35 -> 3.9496711 | T35: =(((I35/C35))^(1/5))-1 -> 1.5620103 | U35: =(((S35/I35))^(1/5))-1 -> 0
B36: Non-Alc. Beverages | C36: =SUM(C33:C35) -> 82.550445 | D36: =SUM(D33:D35) -> 89.230607 | E36: =SUM(E33:E35) -> 126.52523 | F36: =SUM(F33:F35) -> 162.2034 | G36: =SUM(G33:G35) -> 177.53488 | H36: =SUM(H33:H35) -> 215.2532 | I36: =SUM(I33:I35) -> 210.50253 | R36: =SUM(J36:Q36) -> 0 | S36: =R36+I36 -> 210.50253 | T36: =(((I36/C36))^(1/5))-1 -> 0.20588969 | U36: =(((S36/I36))^(1/5))-1 -> 0
A37: MEA | B37: Result | C37: =SUMIFS(AfO!D:D,AfO!$A:$A,$A$30,AfO!$B:$B,$B37)/1000 -> 146.25187 | D37: =SUMIFS(AfO!E:E,AfO!$A:$A,$A$30,AfO!$B:$B,$B37)/1000 -> 160.10378 | E37: =SUMIFS(AfO!F:F,AfO!$A:$A,$A$30,AfO!$B:$B,$B37)/1000 -> 200.5086 | F37: =SUMIFS(AfO!G:G,AfO!$A:$A,$A$30,AfO!$B:$B,$B37)/1000 -> 269.63334 | G37: =SUMIFS(AfO!H:H,AfO!$A:$A,$A$30,AfO!$B:$B,$B37)/1000 -> 288.60083 | H37: =SUMIFS(AfO!I:I,AfO!$A:$A,$A$30,AfO!$B:$B,$B37)/1000 -> 350.2815 | I37: =SUMIFS(AfO!J:J,AfO!$A:$A,$A$30,AfO!$B:$B,$B37)/1000 -> 340.30114 | R37: =SUM(J37:Q37) -> 0 | S37: =R37+I37 -> 340.30114 | T37: =(((I37/C37))^(1/5))-1 -> 0.18400188 | U37: =(((S37/I37))^(1/5))-1 -> 0
A38: TIP | B38: Brewery | C38: =SUMIFS(AfO!D:D,AfO!$A:$A,$A$38,AfO!$B:$B,$B38)/1000 -> 0.11018411 | D38: =SUMIFS(AfO!E:E,AfO!$A:$A,$A$38,AfO!$B:$B,$B38)/1000 -> 0.23603634 | E38: =SUMIFS(AfO!F:F,AfO!$A:$A,$A$38,AfO!$B:$B,$B38)/1000 -> 0.20331586 | F38: =SUMIFS(AfO!G:G,AfO!$A:$A,$A$38,AfO!$B:$B,$B38)/1000 -> 0.24843991 | G38: =SUMIFS(AfO!H:H,AfO!$A:$A,$A$38,AfO!$B:$B,$B38)/1000 -> 0.25705306 | H38: =SUMIFS(AfO!I:I,AfO!$A:$A,$A$38,AfO!$B:$B,$B38)/1000 -> 0.46552909 | I38: =SUMIFS(AfO!J:J,AfO!$A:$A,$A$38,AfO!$B:$B,$B38)/1000 -> 0.27165275 | R38: =SUM(J38:Q38) -> 0 | S38: =R38+I38 -> 0.27165275 | T38: =(((I38/C38))^(1/5))-1 -> 0.19778544 | U38: =(((S38/I38))^(1/5))-1 -> 0
B39: Cider, Wine & Spirit | C39: =SUMIFS(AfO!D:D,AfO!$A:$A,$A$38,AfO!$B:$B,$B39)/1000 -> 1.4041965 | D39: =SUMIFS(AfO!E:E,AfO!$A:$A,$A$38,AfO!$B:$B,$B39)/1000 -> 0.43151864 | E39: =SUMIFS(AfO!F:F,AfO!$A:$A,$A$38,AfO!$B:$B,$B39)/1000 -> 0.84039156 | F39: =SUMIFS(AfO!G:G,AfO!$A:$A,$A$38,AfO!$B:$B,$B39)/1000 -> 1.3543862 | G39: =SUMIFS(AfO!H:H,AfO!$A:$A,$A$38,AfO!$B:$B,$B39)/1000 -> 1.4115636 | H39: =SUMIFS(AfO!I:I,AfO!$A:$A,$A$38,AfO!$B:$B,$B39)/1000 -> 1.5981615 | I39: =SUMIFS(AfO!J:J,AfO!$A:$A,$A$38,AfO!$B:$B,$B39)/1000 -> 1.2010816 | R39: =SUM(J39:Q39) -> 0 | S39: =R39+I39 -> 1.2010816 | T39: =(((I39/C39))^(1/5))-1 -> -0.030765366 | U39: =(((S39/I39))^(1/5))-1 -> 0
B40: Alc. Beverages | C40: =SUM(C38:C39) -> 1.5143806 | D40: =SUM(D38:D39) -> 0.66755498 | E40: =SUM(E38:E39) -> 1.0437074 | F40: =SUM(F38:F39) -> 1.6028261 | G40: =SUM(G38:G39) -> 1.6686167 | H40: =SUM(H38:H39) -> 2.0636906 | I40: =SUM(I38:I39) -> 1.4727343 | R40: =SUM(J40:Q40) -> 0 | S40: =R40+I40 -> 1.4727343 | T40: =(((I40/C40))^(1/5))-1 -> -0.005561626 | U40: =(((S40/I40))^(1/5))-1 -> 0
B41: Juice & Juice Drink | C41: =SUMIFS(AfO!D:D,AfO!$A:$A,$A$38,AfO!$B:$B,$B41)/1000 -> 25.004953 | D41: =SUMIFS(AfO!E:E,AfO!$A:$A,$A$38,AfO!$B:$B,$B41)/1000 -> 29.108342 | E41: =SUMIFS(AfO!F:F,AfO!$A:$A,$A$38,AfO!$B:$B,$B41)/1000 -> 29.574215 | F41: =SUMIFS(AfO!G:G,AfO!$A:$A,$A$38,AfO!$B:$B,$B41)/1000 -> 32.094491 | G41: =SUMIFS(AfO!H:H,AfO!$A:$A,$A$38,AfO!$B:$B,$B41)/1000 -> 36.498247 | H41: =SUMIFS(AfO!I:I,AfO!$A:$A,$A$38,AfO!$B:$B,$B41)/1000 -> 47.849936 | I41: =SUMIFS(AfO!J:J,AfO!$A:$A,$A$38,AfO!$B:$B,$B41)/1000 -> 40.561618 | R41: =SUM(J41:Q41) -> 0 | S41: =R41+I41 -> 40.561618 | T41: =(((I41/C41))^(1/5))-1 -> 0.10158457 | U41: =(((S41/I41))^(1/5))-1 -> 0
...

Sheet X5 Template Goals - Tab 1
L1: Please fill in the yellow fields with your growth targets for X5 (2024 - 2029) - No final values for 2029. They will be calculated (column AE) based on your growth targets! | AO1: For your reference:
L2: X5 Targets (GROWTH VALUE) | U2: X5 Targets (GROWTH VALUE) | AJ2: Sales Results - MS Beverage | AO2: FY Bud 2024
L3: B2C Applications Beverage | U3: B2C Applications Food | AO3: B2C Applications Beverage + Food | BK3: B2C Applications Beverage
B4: Gross Sales ['mio. €] | D4: FY 2019 | E4: FY 2020 | F4: FY 2021 | G4: FY 2022 | H4: FY 2023 | I4: RunRate 2024 | J4: BUD 2024 | K4: Historic Development '19 - '24 RR | L4: Beer & Malt Bev. | M4: Cider, Wine, Spirits | N4: Instant & Dry Bev. | O4: Juices & Juice Drnks | P4: Soft Drinks & Waters | Q4: Sports,Ener,FuncDrnk | R4: Syrups | S4: Tea & Coffee Drinks | U4: All Other Food | V4: Bakery | W4: Cereals & Snacks | X4: Confectionery | Y4: Culinary | Z4: Dairy & Ice Cream | AA4: Functional Food | AB4: Plantbsd Dairy & Ice | AC4: Babyfood | AD4: X5 Growth | AE4: FY 2029 (est.) | AF4: CAGR '19 - '24 | AG4: CAGR '24 - '29 | AH4: X5 Trend | AJ4: Comments | AL4: Gross Sales ['mio. €] | AO4: Beer & Malt Bev. | AP4: Cider, Wine, Spirits | AQ4: Instant & Dry Bev. | AR4: Juices & Juice Drnks | AS4: Soft Drinks & Waters | AT4: Sports,Ener,FuncDrnk | AU4: Syrups | AV4: Tea & Coffee Drinks | AW4: BUD Beverage Appl. | AX4: All Other Food | AY4: Bakery | AZ4: Cereals & Snacks | BA4: Confectionery | BB4: Culinary | BC4: Dairy & Ice Cream | BD4: Functional Food | BE4: Plantbsd Dairy & Ice | BF4: Babyfood | BG4: BUD Food Appl. | BH4: B2C Non-Food | BI4: Total BUD | BK4: Beer & Malt Bev. | BL4: Cider, Wine, Spirits | BM4: Instant & Dry Bev. | BN4: Juices & Juice Drnks | BO4: Soft Drinks & Waters | BP4: Sports,Ener,FuncDrnk | BQ4: Syrups | BR4: Tea & Coffee Drinks | BS4: Result
K5: FY 2029 (est.) | L5: =(SUMIFS('Sales 2019 - 2024'!$L:$L,'Sales 2019 - 2024'!$J:$J,L$4,'Sales 2019 - 2024'!$K:$K,"Result")/1000)+L16 -> 163.92338 | M5: =(SUMIFS('Sales 2019 - 2024'!$L:$L,'Sales 2019 - 2024'!$J:$J,M$4,'Sales 2019 - 2024'!$K:$K,"Result")/1000)+M16 -> 183.24258 | N5: =(SUMIFS('Sales 2019 - 2024'!$L:$L,'Sales 2019 - 2024'!$J:$J,N$4,'Sales 2019 - 2024'!$K:$K,"Result")/1000)+N16 -> 93.893566 | O5: =(SUMIFS('Sales 2019 - 2024'!$L:$L,'Sales 2019 - 2024'!$J:$J,O$4,'Sales 2019 - 2024'!$K:$K,"Result")/1000)+O16 -> 2299.0323 | P5: =(SUMIFS('Sales 2019 - 2024'!$L:$L,'Sales 2019 - 2024'!$J:$J,P$4,'Sales 2019 - 2024'!$K:$K,"Result")/1000)+P16 -> 797.87909 | Q5: =(SUMIFS('Sales 2019 - 2024'!$L:$L,'Sales 2019 - 2024'!$J:$J,Q$4,'Sales 2019 - 2024'!$K:$K,"Result")/1000)+Q16 -> 488.98113 | R5: =(SUMIFS('Sales 2019 - 2024'!$L:$L,'Sales 2019 - 2024'!$J:$J,R$4,'Sales 2019 - 2024'!$K:$K,"Result")/1000)+R16 -> 207.52945 | S5: =(SUMIFS('Sales 2019 - 2024'!$L:$L,'Sales 2019 - 2024'!$J:$J,S$4,'Sales 2019 - 2024'!$K:$K,"Result")/1000)+S16 -> 178.62952 | U5: =(SUMIFS('Sales 2019 - 2024'!$L:$L,'Sales 2019 - 2024'!$J:$J,U$4,'Sales 2019 - 2024'!$K:$K,"Result")/1000)+U16 -> 124.78319 | V5: =(SUMIFS('Sales 2019 - 2024'!$L:$L,'Sales 2019 - 2024'!$J:$J,V$4,'Sales 2019 - 2024'!$K:$K,"Result")/1000)+V16 -> 153.03018 | W5: =(SUMIFS('Sales 2019 - 2024'!$L:$L,'Sales 2019 - 2024'!$J:$J,W$4,'Sales 2019 - 2024'!$K:$K,"Result")/1000)+W16 -> 192.98345 | X5: =(SUMIFS('Sales 2019 - 2024'!$L:$L,'Sales 2019 - 2024'!$J:$J,X$4,'Sales 2019 - 2024'!$K:$K,"Result")/1000)+X16 -> 90.367644 | Y5: =(SUMIFS('Sales 2019 - 2024'!$L:$L,'Sales 2019 - 2024'!$J:$J,Y$4,'Sales 2019 - 2024'!$K:$K,"Result")/1000)+Y16 -> 84.82017 | Z5: =(SUMIFS('Sales 2019 - 2024'!$L:$L,'Sales 2019 - 2024'!$J:$J,Z$4,'Sales 2019 - 2024'!$K:$K,"Result")/1000)+Z16 -> 356.69715 | AA5: =(SUMIFS('Sales 2019 - 2024'!$L:$L,'Sales 2019 - 2024'!$J:$J,AA$4,'Sales 2019 - 2024'!$K:$K,"Result")/1000)+AA16 -> 51.710365 | AB5: =(SUMIFS('Sales 2019 - 2024'!$L:$L,'Sales 2019 - 2024'!$J:$J,AB$4,'Sales 2019 - 2024'!$K:$K,"Result")/1000)+AB16 -> 217.37622 | AC5: =(SUMIFS('Sales 2019 - 2024'!$L:$L,'Sales 2019 - 2024'!$J:$J,AC$4,'Sales 2019 - 2024'!$K:$K,"Result")/1000)+AC16 -> 45 | AF5: Doubled Sales in 5 years
K6: Market Potential | L6: =SUMIFS('Market Potential'!$E:$E,'Market Potential'!$D:$D,'X5 Template Goals - Tab 1'!L$4)/1000 -> 336.503 | M6: =SUMIFS('Market Potential'!$E:$E,'Market Potential'!$D:$D,'X5 Template Goals - Tab 1'!M$4)/1000 -> 2067.045 | N6: =SUMIFS('Market Potential'!$E:$E,'Market Potential'!$D:$D,'X5 Template Goals - Tab 1'!N$4)/1000 -> 431.958 | O6: =SUMIFS('Market Potential'!$E:$E,'Market Potential'!$D:$D,'X5 Template Goals - Tab 1'!O$4)/1000 -> 17024.109 | P6: =SUMIFS('Market Potential'!$E:$E,'Market Potential'!$D:$D,'X5 Template Goals - Tab 1'!P$4)/1000 -> 7355.962 | Q6: =SUMIFS('Market Potential'!$E:$E,'Market Potential'!$D:$D,'X5 Template Goals - Tab 1'!Q$4)/1000 -> 1636.8 | R6: =SUMIFS('Market Potential'!$E:$E,'Market Potential'!$D:$D,'X5 Template Goals - Tab 1'!R$4)/1000 -> 204.088 | S6: =SUMIFS('Market Potential'!$E:$E,'Market Potential'!$D:$D,'X5 Template Goals - Tab 1'!S$4)/1000 -> 731.042 | U6: =SUMIFS('Market Potential'!$E:$E,'Market Potential'!$D:$D,'X5 Template Goals - Tab 1'!U$4)/1000 -> 1026.732 | V6: =SUMIFS('Market Potential'!$E:$E,'Market Potential'!$D:$D,'X5 Template Goals - Tab 1'!V$4)/1000 -> 1910.51 | W6: =SUMIFS('Market Potential'!$E:$E,'Market Potential'!$D:$D,'X5 Template Goals - Tab 1'!W$4)/1000 -> 3812.446 | X6: =SUMIFS('Market Potential'!$E:$E,'Market Potential'!$D:$D,'X5 Template Goals - Tab 1'!X$4)/1000 -> 1558.853 | Y6: =SUMIFS('Market Potential'!$E:$E,'Market Potential'!$D:$D,'X5 Template Goals - Tab 1'!Y$4)/1000 -> 6787.163 | Z6: =SUMIFS('Market Potential'!$E:$E,'Market Potential'!$D:$D,'X5 Template Goals - Tab 1'!Z$4)/1000 -> 4562.299 | AA6: =SUMIFS('Market Potential'!$E:$E,'Market Potential'!$D:$D,'X5 Template Goals - Tab 1'!AA$4)/1000 -> 56.947 | AB6: =SUMIFS('Market Potential'!$E:$E,'Market Potential'!$D:$D,'X5 Template Goals - Tab 1'!AB$4)/1000 -> 802.208 | AC6: =SUMIFS('Market Potential'!$E:$E,'Market Potential'!$D:$D,'X5 Template Goals - Tab 1'!AC$4)/1000 -> 12.111 | AF6: = CAGR of 15%
C7: Region | D7: *mio. € | L7: *mio. € | AD7: *mio. € | AF7: % | AG7: % | AL7: Region | AO7: *mio. € | BK7: *mio. € | BL7: *mio. € | BM7: *mio. € | BN7: *mio. € | BO7: *mio. € | BP7: *mio. € | BQ7: *mio. € | BR7: *mio. € | BS7: *mio. €
